Workbook

Sheet ⚙️ Auto-Update Setup
A1: ⚙️ AUTO-UPDATE SETUP — Two Ways to Pull Live ESPN Results
A3: METHOD 1 — Python Script (Runs outside Excel — most reliable)
A4: 1 | B4: Install Python 3 from python.org if not already installed
A5: 2 | B5: Open Terminal (Mac) or Command Prompt (Windows)
A6: 3 | B6: Run: pip install requests openpyxl
A7: 4 | B7: Put update_bracket.py in the same folder as this Excel file
A8: 5 | B8: Run: python update_bracket.py
A9: ↺ | B9: Re-run anytime during tournament to sync the latest results
A10: ✅ Fastest & most reliable. Results write directly into Master_Results. No Excel setup needed.
A12: METHOD 2 — Power Query (Refresh inside Excel with one click)
A13: 1 | B13: In Excel: click the Data tab → Get Data → Launch Power Query Editor
A14: 2 | B14: Click "New Source" → "Blank Query"
A15: 3 | B15: In the ribbon, click "Advanced Editor"
A16: 4 | B16: Delete all text, then paste the M code starting at row 21 below
A17: 5 | B17: Click Done. Name the query: ESPN_Tournament_Results
A18: 6 | B18: Click "Close & Load To..." → Existing sheet → select ESPN_Data!$A$3
A19: ↺ | B19: After setup: Data → Refresh All (or Ctrl+Alt+F5) to pull latest scores anytime
A20: ✅ Once configured, one-click refresh. Requires Excel desktop (Windows or Mac). Not Excel Online.
A22: POWER QUERY M CODE — Select all lines below and copy into Advanced Editor
A23: let
A24: StartDate = #date(2026, 3, 17),
A25: EndDate = #date(2026, 4, 7),
A26: DateList = List.Dates(StartDate, Duration.Days(EndDate - StartDate) + 1, #duration(1,0,0,0)),
A27: DateStrings = List.Transform(DateList, each Date.ToText(_, "yyyyMMdd")),
A28: FetchDate = (dateStr as text) as list =>
A29: let
A30: Url = "https://site.api.espn.com/apis/site/v2/sports/basketball/mens-college-basketball/scoreboard?groups=100&limit=100&dates=" & dateStr,
A31: Src = try Json.Document(Web.Contents(Url)) otherwise null,
A32: Evts = if Src = null then {} else try Src[events] otherwise {}
... A91: in Result

Sheet 🏆 Leaderboard
A1: 🏆 2026 OFFICE MARCH MADNESS — LEADERBOARD
A2: Scores update automatically as results are entered in Master_Results
A3: Rank | B3: Participant | C3: Champion Pick | D3: Current Score | E3: Pts Remaining | F3: Max Possible
A4: =RANK(D4,$D$4:$D$9,0) -> 1 | B4: Raman | C4: =Raman!D71 -> Duke | D4: =Raman!G73 -> 2 | E4: =Raman!H73 -> 190 | F4: =D4+E4 -> 192
A5: =RANK(D5,$D$4:$D$9,0) -> 5 | B5: Porter | C5: =Porter!D71 -> UConn | D5: =Porter!G73 -> 1 | E5: =Porter!H73 -> 190 | F5: =D5+E5 -> 191
A6: =RANK(D6,$D$4:$D$9,0) -> 5 | B6: Chuck | C6: =Chuck!D71 -> Duke | D6: =Chuck!G73 -> 1 | E6: =Chuck!H73 -> 190 | F6: =D6+E6 -> 191
A7: =RANK(D7,$D$4:$D$9,0) -> 1 | B7: Shelly | C7: =Shelly!D71 -> Duke | D7: =Shelly!G73 -> 2 | E7: =Shelly!H73 -> 190 | F7: =D7+E7 -> 192
A8: =RANK(D8,$D$4:$D$9,0) -> 1 | B8: Kim | C8: =Kim!D71 -> Arizona | D8: =Kim!G73 -> 2 | E8: =Kim!H73 -> 190 | F8: =D8+E8 -> 192
A9: =RANK(D9,$D$4:$D$9,0) -> 1 | B9: Tucker | C9: =Tucker!D71 -> Duke | D9: =Tucker!G73 -> 2 | E9: =Tucker!H73 -> 190 | F9: =D9+E9 -> 192
A11: SCORING GUIDE
A12: Round of 64 | B12: Round of 32 | C12: Sweet 16 | D12: Elite 8 | E12: Final Four | F12: Championship
A13: 1 pt | B13: 2 pts | C13: 4 pts | D13: 8 pts | E13: 16 pts | F13: 32 pts

Sheet Master_Results
A1: 🏀 2026 NCAA TOURNAMENT — OFFICIAL RESULTS
A2: Round | B2: Game ID | C2: Matchup | D2: Actual Winner
A3: ▸ ROUND OF 64
A4: Round of 64 | B4: R64_G1 | C4: (1) Duke vs (16) Siena
A5: Round of 64 | B5: R64_G2 | C5: (8) Ohio St vs (9) TCU | D5: TCU
A6: Round of 64 | B6: R64_G3 | C6: (5) St. John's vs (12) Northern Iowa
A7: Round of 64 | B7: R64_G4 | C7: (4) Kansas vs (13) Cal Baptist
A8: Round of 64 | B8: R64_G5 | C8: (6) Louisville vs (11) South Florida
A9: Round of 64 | B9: R64_G6 | C9: (3) Michigan St vs (14) ND State
A10: Round of 64 | B10: R64_G7 | C10: (7) UCLA vs (10) UCF
A11: Round of 64 | B11: R64_G8 | C11: (2) UConn vs (15) Furman
A12: Round of 64 | B12: R64_G9 | C12: (1) Florida vs (16) Prairie View A&M
A13: Round of 64 | B13: R64_G10 | C13: (8) Clemson vs (9) Iowa
A14: Round of 64 | B14: R64_G11 | C14: (5) Vandy vs (12) McNeese
A15: Round of 64 | B15: R64_G12 | C15: (4) Nebraska vs (13) Troy | D15: Nebraska
A16: Round of 64 | B16: R64_G13 | C16: (6) North Carolina vs (11) VCU
A17: Round of 64 | B17: R64_G14 | C17: (3) Illinois vs (14) Penn
A18: Round of 64 | B18: R64_G15 | C18: (7) St. Mary's vs (10) Texas A&M
A19: Round of 64 | B19: R64_G16 | C19: (2) Houston vs (15) Idaho
A20: Round of 64 | B20: R64_G17 | C20: (1) Arizona vs (16) Long Island
A21: Round of 64 | B21: R64_G18 | C21: (8) Villanova vs (9) Utah St
A22: Round of 64 | B22: R64_G19 | C22: (5) Wisconsin vs (12) High Point
A23: Round of 64 | B23: R64_G20 | C23: (4) Arkansas vs (13) Hawai'i
A24: Round of 64 | B24: R64_G21 | C24: (6) BYU vs (11) Texas
A25: Round of 64 | B25: R64_G22 | C25: (3) Gonzaga vs (14) Kennesaw St
A26: Round of 64 | B26: R64_G23 | C26: (7) Miami (FL) vs (10) Missouri
A27: Round of 64 | B27: R64_G24 | C27: (2) Purdue vs (15) Queens
... A35: Round of 64 | B35: R64_G32 | C35: (2) Iowa St vs (15) Tenn St
A36: ▸ ROUND OF 32
A37: Round of 32 | B37: Rou_G1 | C37: Winner Game 1 & 2
A38: Round of 32 | B38: Rou_G2 | C38: Winner Game 3 & 4
A39: Round of 32 | B39: Rou_G3 | C39: Winner Game 5 & 6
A40: Round of 32 | B40: Rou_G4 | C40: Winner Game 7 & 8
A41: Round of 32 | B41: Rou_G5 | C41: Winner Game 9 & 10
A42: Round of 32 | B42: Rou_G6 | C42: Winner Game 11 & 12
A43: Round of 32 | B43: Rou_G7 | C43: Winner Game 13 & 14
A44: Round of 32 | B44: Rou_G8 | C44: Winner Game 15 & 16
A45: Round of 32 | B45: Rou_G9 | C45: Winner Game 17 & 18
A46: Round of 32 | B46: Rou_G10 | C46: Winner Game 19 & 20
A47: Round of 32 | B47: Rou_G11 | C47: Winner Game 21 & 22
...

Sheet Raman
A1: 🏀 RAMAN'S 2026 MARCH MADNESS BRACKET
A2: Round | B2: Game ID | C2: Matchup | D2: Pick | E2: Pts Value | F2: Result | G2: Pts Earned
A3: ▸ ROUND OF 64 • 1 pt each
A4: Round of 64 | B4: R64_G1 | C4: (1) Duke vs (16) Siena | D4: Duke | E4: 1 | F4: =IF(Master_Results!$D$4="","",IF(D4=Master_Results!$D$4,1,0)) | G4: =IF(F4="","",E4*F4)
A5: Round of 64 | B5: R64_G2 | C5: (8) Ohio St vs (9) TCU | D5: TCU | E5: 1 | F5: =IF(Master_Results!$D$5="","",IF(D5=Master_Results!$D$5,1,0)) -> 1 | G5: =IF(F5="","",E5*F5) -> 1
A6: Round of 64 | B6: R64_G3 | C6: (5) St. John's vs (12) Northern Iowa | D6: St. John | E6: 1 | F6: =IF(Master_Results!$D$6="","",IF(D6=Master_Results!$D$6,1,0)) | G6: =IF(F6="","",E6*F6)
A7: Round of 64 | B7: R64_G4 | C7: (4) Kansas vs (13) Cal Baptist | D7: Kansas | E7: 1 | F7: =IF(Master_Results!$D$7="","",IF(D7=Master_Results!$D$7,1,0)) | G7: =IF(F7="","",E7*F7)
A8: Round of 64 | B8: R64_G5 | C8: (6) Louisville vs (11) South Florida | D8: Louisville | E8: 1 | F8: =IF(Master_Results!$D$8="","",IF(D8=Master_Results!$D$8,1,0)) | G8: =IF(F8="","",E8*F8)
A9: Round of 64 | B9: R64_G6 | C9: (3) Michigan St vs (14) ND State | D9: Mich St | E9: 1 | F9: =IF(Master_Results!$D$9="","",IF(D9=Master_Results!$D$9,1,0)) | G9: =IF(F9="","",E9*F9)
A10: Round of 64 | B10: R64_G7 | C10: (7) UCLA vs (10) UCF | D10: UCLA | E10: 1 | F10: =IF(Master_Results!$D$10="","",IF(D10=Master_Results!$D$10,1,0)) | G10: =IF(F10="","",E10*F10)
A11: Round of 64 | B11: R64_G8 | C11: (2) UConn vs (15) Furman | D11: UConn | E11: 1 | F11: =IF(Master_Results!$D$11="","",IF(D11=Master_Results!$D$11,1,0)) | G11: =IF(F11="","",E11*F11)
A12: Round of 64 | B12: R64_G9 | C12: (1) Florida vs (16) Prairie View A&M | D12: Florida | E12: 1 | F12: =IF(Master_Results!$D$12="","",IF(D12=Master_Results!$D$12,1,0)) | G12: =IF(F12="","",E12*F12)
A13: Round of 64 | B13: R64_G10 | C13: (8) Clemson vs (9) Iowa | D13: Clemson | E13: 1 | F13: =IF(Master_Results!$D$13="","",IF(D13=Master_Results!$D$13,1,0)) | G13: =IF(F13="","",E13*F13)
A14: Round of 64 | B14: R64_G11 | C14: (5) Vandy vs (12) McNeese | D14: Vandy | E14: 1 | F14: =IF(Master_Results!$D$14="","",IF(D14=Master_Results!$D$14,1,0)) | G14: =IF(F14="","",E14*F14)
A15: Round of 64 | B15: R64_G12 | C15: (4) Nebraska vs (13) Troy | D15: Nebraska | E15: 1 | F15: =IF(Master_Results!$D$15="","",IF(D15=Master_Results!$D$15,1,0)) -> 1 | G15: =IF(F15="","",E15*F15) -> 1
A16: Round of 64 | B16: R64_G13 | C16: (6) North Carolina vs (11) VCU | D16: North Carolina | E16: 1 | F16: =IF(Master_Results!$D$16="","",IF(D16=Master_Results!$D$16,1,0)) | G16: =IF(F16="","",E16*F16)
A17: Round of 64 | B17: R64_G14 | C17: (3) Illinois vs (14) Penn | D17: Illinois | E17: 1 | F17: =IF(Master_Results!$D$17="","",IF(D17=Master_Results!$D$17,1,0)) | G17: =IF(F17="","",E17*F17)
A18: Round of 64 | B18: R64_G15 | C18: (7) St. Mary's vs (10) Texas A&M | D18: Texas A&M | E18: 1 | F18: =IF(Master_Results!$D$18="","",IF(D18=Master_Results!$D$18,1,0)) | G18: =IF(F18="","",E18*F18)
A19: Round of 64 | B19: R64_G16 | C19: (2) Houston vs (15) Idaho | D19: Houston | E19: 1 | F19: =IF(Master_Results!$D$19="","",IF(D19=Master_Results!$D$19,1,0)) | G19: =IF(F19="","",E19*F19)
A20: Round of 64 | B20: R64_G17 | C20: (1) Arizona vs (16) Long Island | D20: Arizona | E20: 1 | F20: =IF(Master_Results!$D$20="","",IF(D20=Master_Results!$D$20,1,0)) | G20: =IF(F20="","",E20*F20)
A21: Round of 64 | B21: R64_G18 | C21: (8) Villanova vs (9) Utah St | D21: Villanova | E21: 1 | F21: =IF(Master_Results!$D$21="","",IF(D21=Master_Results!$D$21,1,0)) | G21: =IF(F21="","",E21*F21)
A22: Round of 64 | B22: R64_G19 | C22: (5) Wisconsin vs (12) High Point | D22: Wisconsin | E22: 1 | F22: =IF(Master_Results!$D$22="","",IF(D22=Master_Results!$D$22,1,0)) | G22: =IF(F22="","",E22*F22)
A23: Round of 64 | B23: R64_G20 | C23: (4) Arkansas vs (13) Hawai'i | D23: Arkansas | E23: 1 | F23: =IF(Master_Results!$D$23="","",IF(D23=Master_Results!$D$23,1,0)) | G23: =IF(F23="","",E23*F23)
A24: Round of 64 | B24: R64_G21 | C24: (6) BYU vs (11) Texas | D24: BYU | E24: 1 | F24: =IF(Master_Results!$D$24="","",IF(D24=Master_Results!$D$24,1,0)) | G24: =IF(F24="","",E24*F24)
A25: Round of 64 | B25: R64_G22 | C25: (3) Gonzaga vs (14) Kennesaw St | D25: Gonzaga | E25: 1 | F25: =IF(Master_Results!$D$25="","",IF(D25=Master_Results!$D$25,1,0)) | G25: =IF(F25="","",E25*F25)
A26: Round of 64 | B26: R64_G23 | C26: (7) Miami (FL) vs (10) Missouri | D26: Miami | E26: 1 | F26: =IF(Master_Results!$D$26="","",IF(D26=Master_Results!$D$26,1,0)) | G26: =IF(F26="","",E26*F26)
A27: Round of 64 | B27: R64_G24 | C27: (2) Purdue vs (15) Queens | D27: Purdue | E27: 1 | F27: =IF(Master_Results!$D$27="","",IF(D27=Master_Results!$D$27,1,0)) | G27: =IF(F27="","",E27*F27)
A28: Round of 64 | B28: R64_G25 | C28: (1) Michigan vs (16) Howard | D28: Michigan | E28: 1 | F28: =IF(Master_Results!$D$28="","",IF(D28=Master_Results!$D$28,1,0)) | G28: =IF(F28="","",E28*F28)
A29: Round of 64 | B29: R64_G26 | C29: (8) Georgia vs (9) St. Louis | D29: St. Louis | E29: 1 | F29: =IF(Master_Results!$D$29="","",IF(D29=Master_Results!$D$29,1,0)) | G29: =IF(F29="","",E29*F29)
A30: Round of 64 | B30: R64_G27 | C30: (5) Texas Tech vs (12) Akron | D30: Texas Tech | E30: 1 | F30: =IF(Master_Results!$D$30="","",IF(D30=Master_Results!$D$30,1,0)) | G30: =IF(F30="","",E30*F30)
A31: Round of 64 | B31: R64_G28 | C31: (4) Alabama vs (13) Hofstra | D31: Alabama | E31: 1 | F31: =IF(Master_Results!$D$31="","",IF(D31=Master_Results!$D$31,1,0)) | G31: =IF(F31="","",E31*F31)
A32: Round of 64 | B32: R64_G29 | C32: (6) Tennessee vs (11) Miami (OH) | D32: Tennessee | E32: 1 | F32: =IF(Master_Results!$D$32="","",IF(D32=Master_Results!$D$32,1,0)) | G32: =IF(F32="","",E32*F32)
A33: Round of 64 | B33: R64_G30 | C33: (3) Virginia vs (14) Wright St | D33: Virginia | E33: 1 | F33: =IF(Master_Results!$D$33="","",IF(D33=Master_Results!$D$33,1,0)) | G33: =IF(F33="","",E33*F33)
A34: Round of 64 | B34: R64_G31 | C34: (7) Kentucky vs (10) Santa Clara | D34: Kentucky | E34: 1 | F34: =IF(Master_Results!$D$34="","",IF(D34=Master_Results!$D$34,1,0)) | G34: =IF(F34="","",E34*F34)
A35: Round of 64 | B35: R64_G32 | C35: (2) Iowa St vs (15) Tenn St | D35: Iowa State | E35: 1 | F35: =IF(Master_Results!$D$35="","",IF(D35=Master_Results!$D$35,1,0)) | G35: =IF(F35="","",E35*F35)
A36: ▸ ROUND OF 32 • 2 pts each
A37: Round of 32 | B37: Rou_G1 | C37: Winner Game 1 & 2 | D37: Duke | E37: 2 | F37: =IF(Master_Results!$D$37="","",IF(D37=Master_Results!$D$37,1,0)) | G37: =IF(F37="","",E37*F37)
A38: Round of 32 | B38: Rou_G2 | C38: Winner Game 3 & 4 | D38: St. John | E38: 2 | F38: =IF(Master_Results!$D$38="","",IF(D38=Master_Results!$D$38,1,0)) | G38: =IF(F38="","",E38*F38)
A39: Round of 32 | B39: Rou_G3 | C39: Winner Game 5 & 6 | D39: Mich St | E39: 2 | F39: =IF(Master_Results!$D$39="","",IF(D39=Master_Results!$D$39,1,0)) | G39: =IF(F39="","",E39*F39)
A40: Round of 32 | B40: Rou_G4 | C40: Winner Game 7 & 8 | D40: UCLA | E40: 2 | F40: =IF(Master_Results!$D$40="","",IF(D40=Master_Results!$D$40,1,0)) | G40: =IF(F40="","",E40*F40)
...

Sheet Porter
A1: 🏀 PORTER'S 2026 MARCH MADNESS BRACKET
A2: Round | B2: Game ID | C2: Matchup | D2: Pick | E2: Pts Value | F2: Result | G2: Pts Earned
A3: ▸ ROUND OF 64 • 1 pt each
A4: Round of 64 | B4: R64_G1 | C4: (1) Duke vs (16) Siena | D4: Duke | E4: 1 | F4: =IF(Master_Results!$D$4="","",IF(D4=Master_Results!$D$4,1,0)) | G4: =IF(F4="","",E4*F4)
A5: Round of 64 | B5: R64_G2 | C5: (8) Ohio St vs (9) TCU | D5: Ohio State | E5: 1 | F5: =IF(Master_Results!$D$5="","",IF(D5=Master_Results!$D$5,1,0)) -> 0 | G5: =IF(F5="","",E5*F5) -> 0
A6: Round of 64 | B6: R64_G3 | C6: (5) St. John's vs (12) Northern Iowa | D6: Northern Iowa | E6: 1 | F6: =IF(Master_Results!$D$6="","",IF(D6=Master_Results!$D$6,1,0)) | G6: =IF(F6="","",E6*F6)
A7: Round of 64 | B7: R64_G4 | C7: (4) Kansas vs (13) Cal Baptist | D7: Kansas | E7: 1 | F7: =IF(Master_Results!$D$7="","",IF(D7=Master_Results!$D$7,1,0)) | G7: =IF(F7="","",E7*F7)
A8: Round of 64 | B8: R64_G5 | C8: (6) Louisville vs (11) South Florida | D8: South Florida | E8: 1 | F8: =IF(Master_Results!$D$8="","",IF(D8=Master_Results!$D$8,1,0)) | G8: =IF(F8="","",E8*F8)
A9: Round of 64 | B9: R64_G6 | C9: (3) Michigan St vs (14) ND State | D9: Mich St | E9: 1 | F9: =IF(Master_Results!$D$9="","",IF(D9=Master_Results!$D$9,1,0)) | G9: =IF(F9="","",E9*F9)
A10: Round of 64 | B10: R64_G7 | C10: (7) UCLA vs (10) UCF | D10: UCLA | E10: 1 | F10: =IF(Master_Results!$D$10="","",IF(D10=Master_Results!$D$10,1,0)) | G10: =IF(F10="","",E10*F10)
A11: Round of 64 | B11: R64_G8 | C11: (2) UConn vs (15) Furman | D11: UConn | E11: 1 | F11: =IF(Master_Results!$D$11="","",IF(D11=Master_Results!$D$11,1,0)) | G11: =IF(F11="","",E11*F11)
A12: Round of 64 | B12: R64_G9 | C12: (1) Florida vs (16) Prairie View A&M | D12: Florida | E12: 1 | F12: =IF(Master_Results!$D$12="","",IF(D12=Master_Results!$D$12,1,0)) | G12: =IF(F12="","",E12*F12)
A13: Round of 64 | B13: R64_G10 | C13: (8) Clemson vs (9) Iowa | D13: Clemson | E13: 1 | F13: =IF(Master_Results!$D$13="","",IF(D13=Master_Results!$D$13,1,0)) | G13: =IF(F13="","",E13*F13)
A14: Round of 64 | B14: R64_G11 | C14: (5) Vandy vs (12) McNeese | D14: Vandy | E14: 1 | F14: =IF(Master_Results!$D$14="","",IF(D14=Master_Results!$D$14,1,0)) | G14: =IF(F14="","",E14*F14)
A15: Round of 64 | B15: R64_G12 | C15: (4) Nebraska vs (13) Troy | D15: Nebraska | E15: 1 | F15: =IF(Master_Results!$D$15="","",IF(D15=Master_Results!$D$15,1,0)) -> 1 | G15: =IF(F15="","",E15*F15) -> 1
A16: Round of 64 | B16: R64_G13 | C16: (6) North Carolina vs (11) VCU | D16: North Carolina | E16: 1 | F16: =IF(Master_Results!$D$16="","",IF(D16=Master_Results!$D$16,1,0)) | G16: =IF(F16="","",E16*F16)
A17: Round of 64 | B17: R64_G14 | C17: (3) Illinois vs (14) Penn | D17: Illinois | E17: 1 | F17: =IF(Master_Results!$D$17="","",IF(D17=Master_Results!$D$17,1,0)) | G17: =IF(F17="","",E17*F17)
A18: Round of 64 | B18: R64_G15 | C18: (7) St. Mary's vs (10) Texas A&M | D18: St. Mary's | E18: 1 | F18: =IF(Master_Results!$D$18="","",IF(D18=Master_Results!$D$18,1,0)) | G18: =IF(F18="","",E18*F18)
A19: Round of 64 | B19: R64_G16 | C19: (2) Houston vs (15) Idaho | D19: Houston | E19: 1 | F19: =IF(Master_Results!$D$19="","",IF(D19=Master_Results!$D$19,1,0)) | G19: =IF(F19="","",E19*F19)
A20: Round of 64 | B20: R64_G17 | C20: (1) Arizona vs (16) Long Island | D20: Arizona | E20: 1 | F20: =IF(Master_Results!$D$20="","",IF(D20=Master_Results!$D$20,1,0)) | G20: =IF(F20="","",E20*F20)
A21: Round of 64 | B21: R64_G18 | C21: (8) Villanova vs (9) Utah St | D21: Villanova | E21: 1 | F21: =IF(Master_Results!$D$21="","",IF(D21=Master_Results!$D$21,1,0)) | G21: =IF(F21="","",E21*F21)
A22: Round of 64 | B22: R64_G19 | C22: (5) Wisconsin vs (12) High Point | D22: High Point | E22: 1 | F22: =IF(Master_Results!$D$22="","",IF(D22=Master_Results!$D$22,1,0)) | G22: =IF(F22="","",E22*F22)
A23: Round of 64 | B23: R64_G20 | C23: (4) Arkansas vs (13) Hawai'i | D23: Arkansas | E23: 1 | F23: =IF(Master_Results!$D$23="","",IF(D23=Master_Results!$D$23,1,0)) | G23: =IF(F23="","",E23*F23)
A24: Round of 64 | B24: R64_G21 | C24: (6) BYU vs (11) Texas | D24: BYU | E24: 1 | F24: =IF(Master_Results!$D$24="","",IF(D24=Master_Results!$D$24,1,0)) | G24: =IF(F24="","",E24*F24)
A25: Round of 64 | B25: R64_G22 | C25: (3) Gonzaga vs (14) Kennesaw St | D25: Gonzaga | E25: 1 | F25: =IF(Master_Results!$D$25="","",IF(D25=Master_Results!$D$25,1,0)) | G25: =IF(F25="","",E25*F25)
A26: Round of 64 | B26: R64_G23 | C26: (7) Miami (FL) vs (10) Missouri | D26: Miami | E26: 1 | F26: =IF(Master_Results!$D$26="","",IF(D26=Master_Results!$D$26,1,0)) | G26: =IF(F26="","",E26*F26)
A27: Round of 64 | B27: R64_G24 | C27: (2) Purdue vs (15) Queens | D27: Purdue | E27: 1 | F27: =IF(Master_Results!$D$27="","",IF(D27=Master_Results!$D$27,1,0)) | G27: =IF(F27="","",E27*F27)
A28: Round of 64 | B28: R64_G25 | C28: (1) Michigan vs (16) Howard | D28: Michigan | E28: 1 | F28: =IF(Master_Results!$D$28="","",IF(D28=Master_Results!$D$28,1,0)) | G28: =IF(F28="","",E28*F28)
A29: Round of 64 | B29: R64_G26 | C29: (8) Georgia vs (9) St. Louis | D29: Georgia | E29: 1 | F29: =IF(Master_Results!$D$29="","",IF(D29=Master_Results!$D$29,1,0)) | G29: =IF(F29="","",E29*F29)
A30: Round of 64 | B30: R64_G27 | C30: (5) Texas Tech vs (12) Akron | D30: Texas Tech | E30: 1 | F30: =IF(Master_Results!$D$30="","",IF(D30=Master_Results!$D$30,1,0)) | G30: =IF(F30="","",E30*F30)
A31: Round of 64 | B31: R64_G28 | C31: (4) Alabama vs (13) Hofstra | D31: Alabama | E31: 1 | F31: =IF(Master_Results!$D$31="","",IF(D31=Master_Results!$D$31,1,0)) | G31: =IF(F31="","",E31*F31)
A32: Round of 64 | B32: R64_G29 | C32: (6) Tennessee vs (11) Miami (OH) | D32: Tennessee | E32: 1 | F32: =IF(Master_Results!$D$32="","",IF(D32=Master_Results!$D$32,1,0)) | G32: =IF(F32="","",E32*F32)
A33: Round of 64 | B33: R64_G30 | C33: (3) Virginia vs (14) Wright St | D33: Virginia | E33: 1 | F33: =IF(Master_Results!$D$33="","",IF(D33=Master_Results!$D$33,1,0)) | G33: =IF(F33="","",E33*F33)
A34: Round of 64 | B34: R64_G31 | C34: (7) Kentucky vs (10) Santa Clara | D34: Santa Clara | E34: 1 | F34: =IF(Master_Results!$D$34="","",IF(D34=Master_Results!$D$34,1,0)) | G34: =IF(F34="","",E34*F34)
A35: Round of 64 | B35: R64_G32 | C35: (2) Iowa St vs (15) Tenn St | D35: Iowa State | E35: 1 | F35: =IF(Master_Results!$D$35="","",IF(D35=Master_Results!$D$35,1,0)) | G35: =IF(F35="","",E35*F35)
A36: ▸ ROUND OF 32 • 2 pts each
A37: Round of 32 | B37: Rou_G1 | C37: Winner Game 1 & 2 | D37: Duke | E37: 2 | F37: =IF(Master_Results!$D$37="","",IF(D37=Master_Results!$D$37,1,0)) | G37: =IF(F37="","",E37*F37)
A38: Round of 32 | B38: Rou_G2 | C38: Winner Game 3 & 4 | D38: Kansas | E38: 2 | F38: =IF(Master_Results!$D$38="","",IF(D38=Master_Results!$D$38,1,0)) | G38: =IF(F38="","",E38*F38)
A39: Round of 32 | B39: Rou_G3 | C39: Winner Game 5 & 6 | D39: Mich St | E39: 2 | F39: =IF(Master_Results!$D$39="","",IF(D39=Master_Results!$D$39,1,0)) | G39: =IF(F39="","",E39*F39)
A40: Round of 32 | B40: Rou_G4 | C40: Winner Game 7 & 8 | D40: UConn | E40: 2 | F40: =IF(Master_Results!$D$40="","",IF(D40=Master_Results!$D$40,1,0)) | G40: =IF(F40="","",E40*F40)
...

Sheet Chuck
A1: 🏀 CHUCK'S 2026 MARCH MADNESS BRACKET
A2: Round | B2: Game ID | C2: Matchup | D2: Pick | E2: Pts Value | F2: Result | G2: Pts Earned
A3: ▸ ROUND OF 64 • 1 pt each
A4: Round of 64 | B4: R64_G1 | C4: (1) Duke vs (16) Siena | D4: Duke | E4: 1 | F4: =IF(Master_Results!$D$4="","",IF(D4=Master_Results!$D$4,1,0)) | G4: =IF(F4="","",E4*F4)
A5: Round of 64 | B5: R64_G2 | C5: (8) Ohio St vs (9) TCU | D5: Ohio State | E5: 1 | F5: =IF(Master_Results!$D$5="","",IF(D5=Master_Results!$D$5,1,0)) -> 0 | G5: =IF(F5="","",E5*F5) -> 0
A6: Round of 64 | B6: R64_G3 | C6: (5) St. John's vs (12) Northern Iowa | D6: St. John | E6: 1 | F6: =IF(Master_Results!$D$6="","",IF(D6=Master_Results!$D$6,1,0)) | G6: =IF(F6="","",E6*F6)
A7: Round of 64 | B7: R64_G4 | C7: (4) Kansas vs (13) Cal Baptist | D7: Kansas | E7: 1 | F7: =IF(Master_Results!$D$7="","",IF(D7=Master_Results!$D$7,1,0)) | G7: =IF(F7="","",E7*F7)
A8: Round of 64 | B8: R64_G5 | C8: (6) Louisville vs (11) South Florida | D8: Louisville | E8: 1 | F8: =IF(Master_Results!$D$8="","",IF(D8=Master_Results!$D$8,1,0)) | G8: =IF(F8="","",E8*F8)
A9: Round of 64 | B9: R64_G6 | C9: (3) Michigan St vs (14) ND State | D9: Mich St | E9: 1 | F9: =IF(Master_Results!$D$9="","",IF(D9=Master_Results!$D$9,1,0)) | G9: =IF(F9="","",E9*F9)
A10: Round of 64 | B10: R64_G7 | C10: (7) UCLA vs (10) UCF | D10: UCF | E10: 1 | F10: =IF(Master_Results!$D$10="","",IF(D10=Master_Results!$D$10,1,0)) | G10: =IF(F10="","",E10*F10)
A11: Round of 64 | B11: R64_G8 | C11: (2) UConn vs (15) Furman | D11: UConn | E11: 1 | F11: =IF(Master_Results!$D$11="","",IF(D11=Master_Results!$D$11,1,0)) | G11: =IF(F11="","",E11*F11)
A12: Round of 64 | B12: R64_G9 | C12: (1) Florida vs (16) Prairie View A&M | D12: Florida | E12: 1 | F12: =IF(Master_Results!$D$12="","",IF(D12=Master_Results!$D$12,1,0)) | G12: =IF(F12="","",E12*F12)
A13: Round of 64 | B13: R64_G10 | C13: (8) Clemson vs (9) Iowa | D13: Iowa | E13: 1 | F13: =IF(Master_Results!$D$13="","",IF(D13=Master_Results!$D$13,1,0)) | G13: =IF(F13="","",E13*F13)
A14: Round of 64 | B14: R64_G11 | C14: (5) Vandy vs (12) McNeese | D14: Vandy | E14: 1 | F14: =IF(Master_Results!$D$14="","",IF(D14=Master_Results!$D$14,1,0)) | G14: =IF(F14="","",E14*F14)
A15: Round of 64 | B15: R64_G12 | C15: (4) Nebraska vs (13) Troy | D15: Nebraska | E15: 1 | F15: =IF(Master_Results!$D$15="","",IF(D15=Master_Results!$D$15,1,0)) -> 1 | G15: =IF(F15="","",E15*F15) -> 1
A16: Round of 64 | B16: R64_G13 | C16: (6) North Carolina vs (11) VCU | D16: North Carolina | E16: 1 | F16: =IF(Master_Results!$D$16="","",IF(D16=Master_Results!$D$16,1,0)) | G16: =IF(F16="","",E16*F16)
A17: Round of 64 | B17: R64_G14 | C17: (3) Illinois vs (14) Penn | D17: Illinois | E17: 1 | F17: =IF(Master_Results!$D$17="","",IF(D17=Master_Results!$D$17,1,0)) | G17: =IF(F17="","",E17*F17)
A18: Round of 64 | B18: R64_G15 | C18: (7) St. Mary's vs (10) Texas A&M | D18: St. Mary's | E18: 1 | F18: =IF(Master_Results!$D$18="","",IF(D18=Master_Results!$D$18,1,0)) | G18: =IF(F18="","",E18*F18)
A19: Round of 64 | B19: R64_G16 | C19: (2) Houston vs (15) Idaho | D19: Houston | E19: 1 | F19: =IF(Master_Results!$D$19="","",IF(D19=Master_Results!$D$19,1,0)) | G19: =IF(F19="","",E19*F19)
A20: Round of 64 | B20: R64_G17 | C20: (1) Arizona vs (16) Long Island | D20: Arizona | E20: 1 | F20: =IF(Master_Results!$D$20="","",IF(D20=Master_Results!$D$20,1,0)) | G20: =IF(F20="","",E20*F20)
A21: Round of 64 | B21: R64_G18 | C21: (8) Villanova vs (9) Utah St | D21: Villanova | E21: 1 | F21: =IF(Master_Results!$D$21="","",IF(D21=Master_Results!$D$21,1,0)) | G21: =IF(F21="","",E21*F21)
A22: Round of 64 | B22: R64_G19 | C22: (5) Wisconsin vs (12) High Point | D22: Wisconsin | E22: 1 | F22: =IF(Master_Results!$D$22="","",IF(D22=Master_Results!$D$22,1,0)) | G22: =IF(F22="","",E22*F22)
A23: Round of 64 | B23: R64_G20 | C23: (4) Arkansas vs (13) Hawai'i | D23: Arkansas | E23: 1 | F23: =IF(Master_Results!$D$23="","",IF(D23=Master_Results!$D$23,1,0)) | G23: =IF(F23="","",E23*F23)
A24: Round of 64 | B24: R64_G21 | C24: (6) BYU vs (11) Texas | D24: BYU | E24: 1 | F24: =IF(Master_Results!$D$24="","",IF(D24=Master_Results!$D$24,1,0)) | G24: =IF(F24="","",E24*F24)
A25: Round of 64 | B25: R64_G22 | C25: (3) Gonzaga vs (14) Kennesaw St | D25: Gonzaga | E25: 1 | F25: =IF(Master_Results!$D$25="","",IF(D25=Master_Results!$D$25,1,0)) | G25: =IF(F25="","",E25*F25)
A26: Round of 64 | B26: R64_G23 | C26: (7) Miami (FL) vs (10) Missouri | D26: Miami | E26: 1 | F26: =IF(Master_Results!$D$26="","",IF(D26=Master_Results!$D$26,1,0)) | G26: =IF(F26="","",E26*F26)
A27: Round of 64 | B27: R64_G24 | C27: (2) Purdue vs (15) Queens | D27: Purdue | E27: 1 | F27: =IF(Master_Results!$D$27="","",IF(D27=Master_Results!$D$27,1,0)) | G27: =IF(F27="","",E27*F27)
A28: Round of 64 | B28: R64_G25 | C28: (1) Michigan vs (16) Howard | D28: Michigan | E28: 1 | F28: =IF(Master_Results!$D$28="","",IF(D28=Master_Results!$D$28,1,0)) | G28: =IF(F28="","",E28*F28)
A29: Round of 64 | B29: R64_G26 | C29: (8) Georgia vs (9) St. Louis | D29: St. Louis | E29: 1 | F29: =IF(Master_Results!$D$29="","",IF(D29=Master_Results!$D$29,1,0)) | G29: =IF(F29="","",E29*F29)
A30: Round of 64 | B30: R64_G27 | C30: (5) Texas Tech vs (12) Akron | D30: Texas Tech | E30: 1 | F30: =IF(Master_Results!$D$30="","",IF(D30=Master_Results!$D$30,1,0)) | G30: =IF(F30="","",E30*F30)
A31: Round of 64 | B31: R64_G28 | C31: (4) Alabama vs (13) Hofstra | D31: Alabama | E31: 1 | F31: =IF(Master_Results!$D$31="","",IF(D31=Master_Results!$D$31,1,0)) | G31: =IF(F31="","",E31*F31)
A32: Round of 64 | B32: R64_G29 | C32: (6) Tennessee vs (11) Miami (OH) | D32: Tennessee | E32: 1 | F32: =IF(Master_Results!$D$32="","",IF(D32=Master_Results!$D$32,1,0)) | G32: =IF(F32="","",E32*F32)
A33: Round of 64 | B33: R64_G30 | C33: (3) Virginia vs (14) Wright St | D33: Virginia | E33: 1 | F33: =IF(Master_Results!$D$33="","",IF(D33=Master_Results!$D$33,1,0)) | G33: =IF(F33="","",E33*F33)
A34: Round of 64 | B34: R64_G31 | C34: (7) Kentucky vs (10) Santa Clara | D34: Kentucky | E34: 1 | F34: =IF(Master_Results!$D$34="","",IF(D34=Master_Results!$D$34,1,0)) | G34: =IF(F34="","",E34*F34)
A35: Round of 64 | B35: R64_G32 | C35: (2) Iowa St vs (15) Tenn St | D35: Iowa State | E35: 1 | F35: =IF(Master_Results!$D$35="","",IF(D35=Master_Results!$D$35,1,0)) | G35: =IF(F35="","",E35*F35)
A36: ▸ ROUND OF 32 • 2 pts each
A37: Round of 32 | B37: Rou_G1 | C37: Winner Game 1 & 2 | D37: Duke | E37: 2 | F37: =IF(Master_Results!$D$37="","",IF(D37=Master_Results!$D$37,1,0)) | G37: =IF(F37="","",E37*F37)
A38: Round of 32 | B38: Rou_G2 | C38: Winner Game 3 & 4 | D38: Kansas | E38: 2 | F38: =IF(Master_Results!$D$38="","",IF(D38=Master_Results!$D$38,1,0)) | G38: =IF(F38="","",E38*F38)
A39: Round of 32 | B39: Rou_G3 | C39: Winner Game 5 & 6 | D39: Mich St | E39: 2 | F39: =IF(Master_Results!$D$39="","",IF(D39=Master_Results!$D$39,1,0)) | G39: =IF(F39="","",E39*F39)
A40: Round of 32 | B40: Rou_G4 | C40: Winner Game 7 & 8 | D40: UConn | E40: 2 | F40: =IF(Master_Results!$D$40="","",IF(D40=Master_Results!$D$40,1,0)) | G40: =IF(F40="","",E40*F40)
...

Sheet Shelly
A1: 🏀 SHELLY'S 2026 MARCH MADNESS BRACKET
A2: Round | B2: Game ID | C2: Matchup | D2: Pick | E2: Pts Value | F2: Result | G2: Pts Earned
A3: ▸ ROUND OF 64 • 1 pt each
A4: Round of 64 | B4: R64_G1 | C4: (1) Duke vs (16) Siena | D4: Duke | E4: 1 | F4: =IF(Master_Results!$D$4="","",IF(D4=Master_Results!$D$4,1,0)) | G4: =IF(F4="","",E4*F4)
A5: Round of 64 | B5: R64_G2 | C5: (8) Ohio St vs (9) TCU | D5: TCU | E5: 1 | F5: =IF(Master_Results!$D$5="","",IF(D5=Master_Results!$D$5,1,0)) -> 1 | G5: =IF(F5="","",E5*F5) -> 1
A6: Round of 64 | B6: R64_G3 | C6: (5) St. John's vs (12) Northern Iowa | D6: St. John | E6: 1 | F6: =IF(Master_Results!$D$6="","",IF(D6=Master_Results!$D$6,1,0)) | G6: =IF(F6="","",E6*F6)
A7: Round of 64 | B7: R64_G4 | C7: (4) Kansas vs (13) Cal Baptist | D7: Kansas | E7: 1 | F7: =IF(Master_Results!$D$7="","",IF(D7=Master_Results!$D$7,1,0)) | G7: =IF(F7="","",E7*F7)
A8: Round of 64 | B8: R64_G5 | C8: (6) Louisville vs (11) South Florida | D8: Louisville | E8: 1 | F8: =IF(Master_Results!$D$8="","",IF(D8=Master_Results!$D$8,1,0)) | G8: =IF(F8="","",E8*F8)
A9: Round of 64 | B9: R64_G6 | C9: (3) Michigan St vs (14) ND State | D9: Michigan St | E9: 1 | F9: =IF(Master_Results!$D$9="","",IF(D9=Master_Results!$D$9,1,0)) | G9: =IF(F9="","",E9*F9)
A10: Round of 64 | B10: R64_G7 | C10: (7) UCLA vs (10) UCF | D10: UCLA | E10: 1 | F10: =IF(Master_Results!$D$10="","",IF(D10=Master_Results!$D$10,1,0)) | G10: =IF(F10="","",E10*F10)
A11: Round of 64 | B11: R64_G8 | C11: (2) UConn vs (15) Furman | D11: UConn | E11: 1 | F11: =IF(Master_Results!$D$11="","",IF(D11=Master_Results!$D$11,1,0)) | G11: =IF(F11="","",E11*F11)
A12: Round of 64 | B12: R64_G9 | C12: (1) Florida vs (16) Prairie View A&M | D12: Florida | E12: 1 | F12: =IF(Master_Results!$D$12="","",IF(D12=Master_Results!$D$12,1,0)) | G12: =IF(F12="","",E12*F12)
A13: Round of 64 | B13: R64_G10 | C13: (8) Clemson vs (9) Iowa | D13: Clemson | E13: 1 | F13: =IF(Master_Results!$D$13="","",IF(D13=Master_Results!$D$13,1,0)) | G13: =IF(F13="","",E13*F13)
A14: Round of 64 | B14: R64_G11 | C14: (5) Vandy vs (12) McNeese | D14: Vandy | E14: 1 | F14: =IF(Master_Results!$D$14="","",IF(D14=Master_Results!$D$14,1,0)) | G14: =IF(F14="","",E14*F14)
A15: Round of 64 | B15: R64_G12 | C15: (4) Nebraska vs (13) Troy | D15: Nebraska | E15: 1 | F15: =IF(Master_Results!$D$15="","",IF(D15=Master_Results!$D$15,1,0)) -> 1 | G15: =IF(F15="","",E15*F15) -> 1
A16: Round of 64 | B16: R64_G13 | C16: (6) North Carolina vs (11) VCU | D16: VCU | E16: 1 | F16: =IF(Master_Results!$D$16="","",IF(D16=Master_Results!$D$16,1,0)) | G16: =IF(F16="","",E16*F16)
A17: Round of 64 | B17: R64_G14 | C17: (3) Illinois vs (14) Penn | D17: Illinois | E17: 1 | F17: =IF(Master_Results!$D$17="","",IF(D17=Master_Results!$D$17,1,0)) | G17: =IF(F17="","",E17*F17)
A18: Round of 64 | B18: R64_G15 | C18: (7) St. Mary's vs (10) Texas A&M | D18: St. Mary's | E18: 1 | F18: =IF(Master_Results!$D$18="","",IF(D18=Master_Results!$D$18,1,0)) | G18: =IF(F18="","",E18*F18)
A19: Round of 64 | B19: R64_G16 | C19: (2) Houston vs (15) Idaho | D19: Houston | E19: 1 | F19: =IF(Master_Results!$D$19="","",IF(D19=Master_Results!$D$19,1,0)) | G19: =IF(F19="","",E19*F19)
A20: Round of 64 | B20: R64_G17 | C20: (1) Arizona vs (16) Long Island | D20: Arizona | E20: 1 | F20: =IF(Master_Results!$D$20="","",IF(D20=Master_Results!$D$20,1,0)) | G20: =IF(F20="","",E20*F20)
A21: Round of 64 | B21: R64_G18 | C21: (8) Villanova vs (9) Utah St | D21: Villanova | E21: 1 | F21: =IF(Master_Results!$D$21="","",IF(D21=Master_Results!$D$21,1,0)) | G21: =IF(F21="","",E21*F21)
A22: Round of 64 | B22: R64_G19 | C22: (5) Wisconsin vs (12) High Point | D22: Wisconsin | E22: 1 | F22: =IF(Master_Results!$D$22="","",IF(D22=Master_Results!$D$22,1,0)) | G22: =IF(F22="","",E22*F22)
A23: Round of 64 | B23: R64_G20 | C23: (4) Arkansas vs (13) Hawai'i | D23: Arkansas | E23: 1 | F23: =IF(Master_Results!$D$23="","",IF(D23=Master_Results!$D$23,1,0)) | G23: =IF(F23="","",E23*F23)
A24: Round of 64 | B24: R64_G21 | C24: (6) BYU vs (11) Texas | D24: BYU | E24: 1 | F24: =IF(Master_Results!$D$24="","",IF(D24=Master_Results!$D$24,1,0)) | G24: =IF(F24="","",E24*F24)
A25: Round of 64 | B25: R64_G22 | C25: (3) Gonzaga vs (14) Kennesaw St | D25: Gonzaga | E25: 1 | F25: =IF(Master_Results!$D$25="","",IF(D25=Master_Results!$D$25,1,0)) | G25: =IF(F25="","",E25*F25)
A26: Round of 64 | B26: R64_G23 | C26: (7) Miami (FL) vs (10) Missouri | D26: Miami | E26: 1 | F26: =IF(Master_Results!$D$26="","",IF(D26=Master_Results!$D$26,1,0)) | G26: =IF(F26="","",E26*F26)
A27: Round of 64 | B27: R64_G24 | C27: (2) Purdue vs (15) Queens | D27: Purdue | E27: 1 | F27: =IF(Master_Results!$D$27="","",IF(D27=Master_Results!$D$27,1,0)) | G27: =IF(F27="","",E27*F27)
A28: Round of 64 | B28: R64_G25 | C28: (1) Michigan vs (16) Howard | D28: Michigan | E28: 1 | F28: =IF(Master_Results!$D$28="","",IF(D28=Master_Results!$D$28,1,0)) | G28: =IF(F28="","",E28*F28)
A29: Round of 64 | B29: R64_G26 | C29: (8) Georgia vs (9) St. Louis | D29: Georgia | E29: 1 | F29: =IF(Master_Results!$D$29="","",IF(D29=Master_Results!$D$29,1,0)) | G29: =IF(F29="","",E29*F29)
A30: Round of 64 | B30: R64_G27 | C30: (5) Texas Tech vs (12) Akron | D30: Akron | E30: 1 | F30: =IF(Master_Results!$D$30="","",IF(D30=Master_Results!$D$30,1,0)) | G30: =IF(F30="","",E30*F30)
A31: Round of 64 | B31: R64_G28 | C31: (4) Alabama vs (13) Hofstra | D31: Alabama | E31: 1 | F31: =IF(Master_Results!$D$31="","",IF(D31=Master_Results!$D$31,1,0)) | G31: =IF(F31="","",E31*F31)
A32: Round of 64 | B32: R64_G29 | C32: (6) Tennessee vs (11) Miami (OH) | D32: Tennessee | E32: 1 | F32: =IF(Master_Results!$D$32="","",IF(D32=Master_Results!$D$32,1,0)) | G32: =IF(F32="","",E32*F32)
A33: Round of 64 | B33: R64_G30 | C33: (3) Virginia vs (14) Wright St | D33: Virginia | E33: 1 | F33: =IF(Master_Results!$D$33="","",IF(D33=Master_Results!$D$33,1,0)) | G33: =IF(F33="","",E33*F33)
A34: Round of 64 | B34: R64_G31 | C34: (7) Kentucky vs (10) Santa Clara | D34: Kentucky | E34: 1 | F34: =IF(Master_Results!$D$34="","",IF(D34=Master_Results!$D$34,1,0)) | G34: =IF(F34="","",E34*F34)
A35: Round of 64 | B35: R64_G32 | C35: (2) Iowa St vs (15) Tenn St | D35: Iowa State | E35: 1 | F35: =IF(Master_Results!$D$35="","",IF(D35=Master_Results!$D$35,1,0)) | G35: =IF(F35="","",E35*F35)
A36: ▸ ROUND OF 32 • 2 pts each
A37: Round of 32 | B37: Rou_G1 | C37: Winner Game 1 & 2 | D37: Duke | E37: 2 | F37: =IF(Master_Results!$D$37="","",IF(D37=Master_Results!$D$37,1,0)) | G37: =IF(F37="","",E37*F37)
A38: Round of 32 | B38: Rou_G2 | C38: Winner Game 3 & 4 | D38: Kansas | E38: 2 | F38: =IF(Master_Results!$D$38="","",IF(D38=Master_Results!$D$38,1,0)) | G38: =IF(F38="","",E38*F38)
A39: Round of 32 | B39: Rou_G3 | C39: Winner Game 5 & 6 | D39: Michigan St | E39: 2 | F39: =IF(Master_Results!$D$39="","",IF(D39=Master_Results!$D$39,1,0)) | G39: =IF(F39="","",E39*F39)
A40: Round of 32 | B40: Rou_G4 | C40: Winner Game 7 & 8 | D40: UConn | E40: 2 | F40: =IF(Master_Results!$D$40="","",IF(D40=Master_Results!$D$40,1,0)) | G40: =IF(F40="","",E40*F40)
...

Sheet Kim
A1: 🏀 KIM'S 2026 MARCH MADNESS BRACKET
A2: Round | B2: Game ID | C2: Matchup | D2: Pick | E2: Pts Value | F2: Result | G2: Pts Earned
A3: ▸ ROUND OF 64 • 1 pt each
A4: Round of 64 | B4: R64_G1 | C4: (1) Duke vs (16) Siena | D4: Duke | E4: 1 | F4: =IF(Master_Results!$D$4="","",IF(D4=Master_Results!$D$4,1,0)) | G4: =IF(F4="","",E4*F4)
A5: Round of 64 | B5: R64_G2 | C5: (8) Ohio St vs (9) TCU | D5: TCU | E5: 1 | F5: =IF(Master_Results!$D$5="","",IF(D5=Master_Results!$D$5,1,0)) -> 1 | G5: =IF(F5="","",E5*F5) -> 1
A6: Round of 64 | B6: R64_G3 | C6: (5) St. John's vs (12) Northern Iowa | D6: St. John | E6: 1 | F6: =IF(Master_Results!$D$6="","",IF(D6=Master_Results!$D$6,1,0)) | G6: =IF(F6="","",E6*F6)
A7: Round of 64 | B7: R64_G4 | C7: (4) Kansas vs (13) Cal Baptist | D7: Kansas | E7: 1 | F7: =IF(Master_Results!$D$7="","",IF(D7=Master_Results!$D$7,1,0)) | G7: =IF(F7="","",E7*F7)
A8: Round of 64 | B8: R64_G5 | C8: (6) Louisville vs (11) South Florida | D8: Louisville | E8: 1 | F8: =IF(Master_Results!$D$8="","",IF(D8=Master_Results!$D$8,1,0)) | G8: =IF(F8="","",E8*F8)
A9: Round of 64 | B9: R64_G6 | C9: (3) Michigan St vs (14) ND State | D9: Mich St | E9: 1 | F9: =IF(Master_Results!$D$9="","",IF(D9=Master_Results!$D$9,1,0)) | G9: =IF(F9="","",E9*F9)
A10: Round of 64 | B10: R64_G7 | C10: (7) UCLA vs (10) UCF | D10: UCF | E10: 1 | F10: =IF(Master_Results!$D$10="","",IF(D10=Master_Results!$D$10,1,0)) | G10: =IF(F10="","",E10*F10)
A11: Round of 64 | B11: R64_G8 | C11: (2) UConn vs (15) Furman | D11: UConn | E11: 1 | F11: =IF(Master_Results!$D$11="","",IF(D11=Master_Results!$D$11,1,0)) | G11: =IF(F11="","",E11*F11)
A12: Round of 64 | B12: R64_G9 | C12: (1) Florida vs (16) Prairie View A&M | D12: Florida | E12: 1 | F12: =IF(Master_Results!$D$12="","",IF(D12=Master_Results!$D$12,1,0)) | G12: =IF(F12="","",E12*F12)
A13: Round of 64 | B13: R64_G10 | C13: (8) Clemson vs (9) Iowa | D13: Iowa | E13: 1 | F13: =IF(Master_Results!$D$13="","",IF(D13=Master_Results!$D$13,1,0)) | G13: =IF(F13="","",E13*F13)
A14: Round of 64 | B14: R64_G11 | C14: (5) Vandy vs (12) McNeese | D14: Vandy | E14: 1 | F14: =IF(Master_Results!$D$14="","",IF(D14=Master_Results!$D$14,1,0)) | G14: =IF(F14="","",E14*F14)
A15: Round of 64 | B15: R64_G12 | C15: (4) Nebraska vs (13) Troy | D15: Nebraska | E15: 1 | F15: =IF(Master_Results!$D$15="","",IF(D15=Master_Results!$D$15,1,0)) -> 1 | G15: =IF(F15="","",E15*F15) -> 1
A16: Round of 64 | B16: R64_G13 | C16: (6) North Carolina vs (11) VCU | D16: North Carolina | E16: 1 | F16: =IF(Master_Results!$D$16="","",IF(D16=Master_Results!$D$16,1,0)) | G16: =IF(F16="","",E16*F16)
A17: Round of 64 | B17: R64_G14 | C17: (3) Illinois vs (14) Penn | D17: Illinois | E17: 1 | F17: =IF(Master_Results!$D$17="","",IF(D17=Master_Results!$D$17,1,0)) | G17: =IF(F17="","",E17*F17)
A18: Round of 64 | B18: R64_G15 | C18: (7) St. Mary's vs (10) Texas A&M | D18: Texas A&M | E18: 1 | F18: =IF(Master_Results!$D$18="","",IF(D18=Master_Results!$D$18,1,0)) | G18: =IF(F18="","",E18*F18)
A19: Round of 64 | B19: R64_G16 | C19: (2) Houston vs (15) Idaho | D19: Houston | E19: 1 | F19: =IF(Master_Results!$D$19="","",IF(D19=Master_Results!$D$19,1,0)) | G19: =IF(F19="","",E19*F19)
A20: Round of 64 | B20: R64_G17 | C20: (1) Arizona vs (16) Long Island | D20: Arizona | E20: 1 | F20: =IF(Master_Results!$D$20="","",IF(D20=Master_Results!$D$20,1,0)) | G20: =IF(F20="","",E20*F20)
A21: Round of 64 | B21: R64_G18 | C21: (8) Villanova vs (9) Utah St | D21: Villanova | E21: 1 | F21: =IF(Master_Results!$D$21="","",IF(D21=Master_Results!$D$21,1,0)) | G21: =IF(F21="","",E21*F21)
A22: Round of 64 | B22: R64_G19 | C22: (5) Wisconsin vs (12) High Point | D22: Wisconsin | E22: 1 | F22: =IF(Master_Results!$D$22="","",IF(D22=Master_Results!$D$22,1,0)) | G22: =IF(F22="","",E22*F22)
A23: Round of 64 | B23: R64_G20 | C23: (4) Arkansas vs (13) Hawai'i | D23: Arkansas | E23: 1 | F23: =IF(Master_Results!$D$23="","",IF(D23=Master_Results!$D$23,1,0)) | G23: =IF(F23="","",E23*F23)
A24: Round of 64 | B24: R64_G21 | C24: (6) BYU vs (11) Texas | D24: BYU | E24: 1 | F24: =IF(Master_Results!$D$24="","",IF(D24=Master_Results!$D$24,1,0)) | G24: =IF(F24="","",E24*F24)
A25: Round of 64 | B25: R64_G22 | C25: (3) Gonzaga vs (14) Kennesaw St | D25: Gonzaga | E25: 1 | F25: =IF(Master_Results!$D$25="","",IF(D25=Master_Results!$D$25,1,0)) | G25: =IF(F25="","",E25*F25)
A26: Round of 64 | B26: R64_G23 | C26: (7) Miami (FL) vs (10) Missouri | D26: Missouri | E26: 1 | F26: =IF(Master_Results!$D$26="","",IF(D26=Master_Results!$D$26,1,0)) | G26: =IF(F26="","",E26*F26)
A27: Round of 64 | B27: R64_G24 | C27: (2) Purdue vs (15) Queens | D27: Purdue | E27: 1 | F27: =IF(Master_Results!$D$27="","",IF(D27=Master_Results!$D$27,1,0)) | G27: =IF(F27="","",E27*F27)
A28: Round of 64 | B28: R64_G25 | C28: (1) Michigan vs (16) Howard | D28: Michigan | E28: 1 | F28: =IF(Master_Results!$D$28="","",IF(D28=Master_Results!$D$28,1,0)) | G28: =IF(F28="","",E28*F28)
A29: Round of 64 | B29: R64_G26 | C29: (8) Georgia vs (9) St. Louis | D29: Georgia | E29: 1 | F29: =IF(Master_Results!$D$29="","",IF(D29=Master_Results!$D$29,1,0)) | G29: =IF(F29="","",E29*F29)
A30: Round of 64 | B30: R64_G27 | C30: (5) Texas Tech vs (12) Akron | D30: Texas Tech | E30: 1 | F30: =IF(Master_Results!$D$30="","",IF(D30=Master_Results!$D$30,1,0)) | G30: =IF(F30="","",E30*F30)
A31: Round of 64 | B31: R64_G28 | C31: (4) Alabama vs (13) Hofstra | D31: Alabama | E31: 1 | F31: =IF(Master_Results!$D$31="","",IF(D31=Master_Results!$D$31,1,0)) | G31: =IF(F31="","",E31*F31)
A32: Round of 64 | B32: R64_G29 | C32: (6) Tennessee vs (11) Miami (OH) | D32: Tennessee | E32: 1 | F32: =IF(Master_Results!$D$32="","",IF(D32=Master_Results!$D$32,1,0)) | G32: =IF(F32="","",E32*F32)
A33: Round of 64 | B33: R64_G30 | C33: (3) Virginia vs (14) Wright St | D33: Virginia | E33: 1 | F33: =IF(Master_Results!$D$33="","",IF(D33=Master_Results!$D$33,1,0)) | G33: =IF(F33="","",E33*F33)
A34: Round of 64 | B34: R64_G31 | C34: (7) Kentucky vs (10) Santa Clara | D34: Kentucky | E34: 1 | F34: =IF(Master_Results!$D$34="","",IF(D34=Master_Results!$D$34,1,0)) | G34: =IF(F34="","",E34*F34)
A35: Round of 64 | B35: R64_G32 | C35: (2) Iowa St vs (15) Tenn St | D35: Iowa State | E35: 1 | F35: =IF(Master_Results!$D$35="","",IF(D35=Master_Results!$D$35,1,0)) | G35: =IF(F35="","",E35*F35)
A36: ▸ ROUND OF 32 • 2 pts each
A37: Round of 32 | B37: Rou_G1 | C37: Winner Game 1 & 2 | D37: Duke | E37: 2 | F37: =IF(Master_Results!$D$37="","",IF(D37=Master_Results!$D$37,1,0)) | G37: =IF(F37="","",E37*F37)
A38: Round of 32 | B38: Rou_G2 | C38: Winner Game 3 & 4 | D38: Kansas | E38: 2 | F38: =IF(Master_Results!$D$38="","",IF(D38=Master_Results!$D$38,1,0)) | G38: =IF(F38="","",E38*F38)
A39: Round of 32 | B39: Rou_G3 | C39: Winner Game 5 & 6 | D39: Mich St | E39: 2 | F39: =IF(Master_Results!$D$39="","",IF(D39=Master_Results!$D$39,1,0)) | G39: =IF(F39="","",E39*F39)
A40: Round of 32 | B40: Rou_G4 | C40: Winner Game 7 & 8 | D40: UConn | E40: 2 | F40: =IF(Master_Results!$D$40="","",IF(D40=Master_Results!$D$40,1,0)) | G40: =IF(F40="","",E40*F40)
...

Sheet Tucker
A1: 🏀 TUCKER'S 2026 MARCH MADNESS BRACKET
A2: Round | B2: Game ID | C2: Matchup | D2: Pick | E2: Pts Value | F2: Result | G2: Pts Earned
A3: ▸ ROUND OF 64 • 1 pt each
A4: Round of 64 | B4: R64_G1 | C4: (1) Duke vs (16) Siena | D4: Duke | E4: 1 | F4: =IF(Master_Results!$D$4="","",IF(D4=Master_Results!$D$4,1,0)) | G4: =IF(F4="","",E4*F4)
A5: Round of 64 | B5: R64_G2 | C5: (8) Ohio St vs (9) TCU | D5: TCU | E5: 1 | F5: =IF(Master_Results!$D$5="","",IF(D5=Master_Results!$D$5,1,0)) -> 1 | G5: =IF(F5="","",E5*F5) -> 1
A6: Round of 64 | B6: R64_G3 | C6: (5) St. John's vs (12) Northern Iowa | D6: St. John's | E6: 1 | F6: =IF(Master_Results!$D$6="","",IF(D6=Master_Results!$D$6,1,0)) | G6: =IF(F6="","",E6*F6)
A7: Round of 64 | B7: R64_G4 | C7: (4) Kansas vs (13) Cal Baptist | D7: Kansas | E7: 1 | F7: =IF(Master_Results!$D$7="","",IF(D7=Master_Results!$D$7,1,0)) | G7: =IF(F7="","",E7*F7)
A8: Round of 64 | B8: R64_G5 | C8: (6) Louisville vs (11) South Florida | D8: South Florida | E8: 1 | F8: =IF(Master_Results!$D$8="","",IF(D8=Master_Results!$D$8,1,0)) | G8: =IF(F8="","",E8*F8)
A9: Round of 64 | B9: R64_G6 | C9: (3) Michigan St vs (14) ND State | D9: Mich St | E9: 1 | F9: =IF(Master_Results!$D$9="","",IF(D9=Master_Results!$D$9,1,0)) | G9: =IF(F9="","",E9*F9)
A10: Round of 64 | B10: R64_G7 | C10: (7) UCLA vs (10) UCF | D10: UCF | E10: 1 | F10: =IF(Master_Results!$D$10="","",IF(D10=Master_Results!$D$10,1,0)) | G10: =IF(F10="","",E10*F10)
A11: Round of 64 | B11: R64_G8 | C11: (2) UConn vs (15) Furman | D11: UConn | E11: 1 | F11: =IF(Master_Results!$D$11="","",IF(D11=Master_Results!$D$11,1,0)) | G11: =IF(F11="","",E11*F11)
A12: Round of 64 | B12: R64_G9 | C12: (1) Florida vs (16) Prairie View A&M | D12: Florida | E12: 1 | F12: =IF(Master_Results!$D$12="","",IF(D12=Master_Results!$D$12,1,0)) | G12: =IF(F12="","",E12*F12)
A13: Round of 64 | B13: R64_G10 | C13: (8) Clemson vs (9) Iowa | D13: Iowa | E13: 1 | F13: =IF(Master_Results!$D$13="","",IF(D13=Master_Results!$D$13,1,0)) | G13: =IF(F13="","",E13*F13)
A14: Round of 64 | B14: R64_G11 | C14: (5) Vandy vs (12) McNeese | D14: Vandy | E14: 1 | F14: =IF(Master_Results!$D$14="","",IF(D14=Master_Results!$D$14,1,0)) | G14: =IF(F14="","",E14*F14)
A15: Round of 64 | B15: R64_G12 | C15: (4) Nebraska vs (13) Troy | D15: Nebraska | E15: 1 | F15: =IF(Master_Results!$D$15="","",IF(D15=Master_Results!$D$15,1,0)) -> 1 | G15: =IF(F15="","",E15*F15) -> 1
A16: Round of 64 | B16: R64_G13 | C16: (6) North Carolina vs (11) VCU | D16: VCU | E16: 1 | F16: =IF(Master_Results!$D$16="","",IF(D16=Master_Results!$D$16,1,0)) | G16: =IF(F16="","",E16*F16)
A17: Round of 64 | B17: R64_G14 | C17: (3) Illinois vs (14) Penn | D17: Illinois | E17: 1 | F17: =IF(Master_Results!$D$17="","",IF(D17=Master_Results!$D$17,1,0)) | G17: =IF(F17="","",E17*F17)
A18: Round of 64 | B18: R64_G15 | C18: (7) St. Mary's vs (10) Texas A&M | D18: St. Mary | E18: 1 | F18: =IF(Master_Results!$D$18="","",IF(D18=Master_Results!$D$18,1,0)) | G18: =IF(F18="","",E18*F18)
A19: Round of 64 | B19: R64_G16 | C19: (2) Houston vs (15) Idaho | D19: Houston | E19: 1 | F19: =IF(Master_Results!$D$19="","",IF(D19=Master_Results!$D$19,1,0)) | G19: =IF(F19="","",E19*F19)
A20: Round of 64 | B20: R64_G17 | C20: (1) Arizona vs (16) Long Island | D20: Arizona | E20: 1 | F20: =IF(Master_Results!$D$20="","",IF(D20=Master_Results!$D$20,1,0)) | G20: =IF(F20="","",E20*F20)
A21: Round of 64 | B21: R64_G18 | C21: (8) Villanova vs (9) Utah St | D21: Villanova | E21: 1 | F21: =IF(Master_Results!$D$21="","",IF(D21=Master_Results!$D$21,1,0)) | G21: =IF(F21="","",E21*F21)
A22: Round of 64 | B22: R64_G19 | C22: (5) Wisconsin vs (12) High Point | D22: Wisconsin | E22: 1 | F22: =IF(Master_Results!$D$22="","",IF(D22=Master_Results!$D$22,1,0)) | G22: =IF(F22="","",E22*F22)
A23: Round of 64 | B23: R64_G20 | C23: (4) Arkansas vs (13) Hawai'i | D23: Arkansas | E23: 1 | F23: =IF(Master_Results!$D$23="","",IF(D23=Master_Results!$D$23,1,0)) | G23: =IF(F23="","",E23*F23)
A24: Round of 64 | B24: R64_G21 | C24: (6) BYU vs (11) Texas | D24: BYU | E24: 1 | F24: =IF(Master_Results!$D$24="","",IF(D24=Master_Results!$D$24,1,0)) | G24: =IF(F24="","",E24*F24)
A25: Round of 64 | B25: R64_G22 | C25: (3) Gonzaga vs (14) Kennesaw St | D25: Gonzaga | E25: 1 | F25: =IF(Master_Results!$D$25="","",IF(D25=Master_Results!$D$25,1,0)) | G25: =IF(F25="","",E25*F25)
A26: Round of 64 | B26: R64_G23 | C26: (7) Miami (FL) vs (10) Missouri | D26: Miami | E26: 1 | F26: =IF(Master_Results!$D$26="","",IF(D26=Master_Results!$D$26,1,0)) | G26: =IF(F26="","",E26*F26)
A27: Round of 64 | B27: R64_G24 | C27: (2) Purdue vs (15) Queens | D27: Purdue | E27: 1 | F27: =IF(Master_Results!$D$27="","",IF(D27=Master_Results!$D$27,1,0)) | G27: =IF(F27="","",E27*F27)
A28: Round of 64 | B28: R64_G25 | C28: (1) Michigan vs (16) Howard | D28: Michigan | E28: 1 | F28: =IF(Master_Results!$D$28="","",IF(D28=Master_Results!$D$28,1,0)) | G28: =IF(F28="","",E28*F28)
A29: Round of 64 | B29: R64_G26 | C29: (8) Georgia vs (9) St. Louis | D29: Georgia | E29: 1 | F29: =IF(Master_Results!$D$29="","",IF(D29=Master_Results!$D$29,1,0)) | G29: =IF(F29="","",E29*F29)
A30: Round of 64 | B30: R64_G27 | C30: (5) Texas Tech vs (12) Akron | D30: Texas Tech | E30: 1 | F30: =IF(Master_Results!$D$30="","",IF(D30=Master_Results!$D$30,1,0)) | G30: =IF(F30="","",E30*F30)
A31: Round of 64 | B31: R64_G28 | C31: (4) Alabama vs (13) Hofstra | D31: Alabama | E31: 1 | F31: =IF(Master_Results!$D$31="","",IF(D31=Master_Results!$D$31,1,0)) | G31: =IF(F31="","",E31*F31)
A32: Round of 64 | B32: R64_G29 | C32: (6) Tennessee vs (11) Miami (OH) | D32: Tennessee | E32: 1 | F32: =IF(Master_Results!$D$32="","",IF(D32=Master_Results!$D$32,1,0)) | G32: =IF(F32="","",E32*F32)
A33: Round of 64 | B33: R64_G30 | C33: (3) Virginia vs (14) Wright St | D33: Virginia | E33: 1 | F33: =IF(Master_Results!$D$33="","",IF(D33=Master_Results!$D$33,1,0)) | G33: =IF(F33="","",E33*F33)
A34: Round of 64 | B34: R64_G31 | C34: (7) Kentucky vs (10) Santa Clara | D34: Kentucky | E34: 1 | F34: =IF(Master_Results!$D$34="","",IF(D34=Master_Results!$D$34,1,0)) | G34: =IF(F34="","",E34*F34)
A35: Round of 64 | B35: R64_G32 | C35: (2) Iowa St vs (15) Tenn St | D35: Iowa | E35: 1 | F35: =IF(Master_Results!$D$35="","",IF(D35=Master_Results!$D$35,1,0)) | G35: =IF(F35="","",E35*F35)
A36: ▸ ROUND OF 32 • 2 pts each
A37: Round of 32 | B37: Rou_G1 | C37: Winner Game 1 & 2 | D37: Duke | E37: 2 | F37: =IF(Master_Results!$D$37="","",IF(D37=Master_Results!$D$37,1,0)) | G37: =IF(F37="","",E37*F37)
A38: Round of 32 | B38: Rou_G2 | C38: Winner Game 3 & 4 | D38: Kansas | E38: 2 | F38: =IF(Master_Results!$D$38="","",IF(D38=Master_Results!$D$38,1,0)) | G38: =IF(F38="","",E38*F38)
A39: Round of 32 | B39: Rou_G3 | C39: Winner Game 5 & 6 | D39: Mich St | E39: 2 | F39: =IF(Master_Results!$D$39="","",IF(D39=Master_Results!$D$39,1,0)) | G39: =IF(F39="","",E39*F39)
A40: Round of 32 | B40: Rou_G4 | C40: Winner Game 7 & 8 | D40: UConn | E40: 2 | F40: =IF(Master_Results!$D$40="","",IF(D40=Master_Results!$D$40,1,0)) | G40: =IF(F40="","",E40*F40)
...

Sheet 📊 Comparison
A1: 📊 HEAD-TO-HEAD PICK COMPARISON — All Participants
A2: Round | B2: Matchup | C2: Actual Winner | D2: Raman | E2: Porter | F2: Chuck | G2: Shelly | H2: Kim | I2: Tucker
A3: ▸ ROUND OF 64
A4: Round of 64 | B4: (1) Duke vs (16) Siena | C4: =Master_Results!D2 -> Actual Winner | D4: =Raman!D4 -> Duke | E4: =Porter!D4 -> Duke | F4: =Chuck!D4 -> Duke | G4: =Shelly!D4 -> Duke | H4: =Kim!D4 -> Duke | I4: =Tucker!D4 -> Duke
A5: Round of 64 | B5: (8) Ohio St vs (9) TCU | C5: =Master_Results!D3 -> 0 | D5: =Raman!D5 -> TCU | E5: =Porter!D5 -> Ohio State | F5: =Chuck!D5 -> Ohio State | G5: =Shelly!D5 -> TCU | H5: =Kim!D5 -> TCU | I5: =Tucker!D5 -> TCU
A6: Round of 64 | B6: (5) St. John's vs (12) Northern Iowa | C6: =Master_Results!D4 -> 0 | D6: =Raman!D6 -> St. John | E6: =Porter!D6 -> Northern Iowa | F6: =Chuck!D6 -> St. John | G6: =Shelly!D6 -> St. John | H6: =Kim!D6 -> St. John | I6: =Tucker!D6 -> St. John's
A7: Round of 64 | B7: (4) Kansas vs (13) Cal Baptist | C7: =Master_Results!D5 -> TCU | D7: =Raman!D7 -> Kansas | E7: =Porter!D7 -> Kansas | F7: =Chuck!D7 -> Kansas | G7: =Shelly!D7 -> Kansas | H7: =Kim!D7 -> Kansas | I7: =Tucker!D7 -> Kansas
A8: Round of 64 | B8: (6) Louisville vs (11) South Florida | C8: =Master_Results!D6 -> 0 | D8: =Raman!D8 -> Louisville | E8: =Porter!D8 -> South Florida | F8: =Chuck!D8 -> Louisville | G8: =Shelly!D8 -> Louisville | H8: =Kim!D8 -> Louisville | I8: =Tucker!D8 -> South Florida
A9: Round of 64 | B9: (3) Michigan St vs (14) ND State | C9: =Master_Results!D7 -> 0 | D9: =Raman!D9 -> Mich St | E9: =Porter!D9 -> Mich St | F9: =Chuck!D9 -> Mich St | G9: =Shelly!D9 -> Michigan St | H9: =Kim!D9 -> Mich St | I9: =Tucker!D9 -> Mich St
A10: Round of 64 | B10: (7) UCLA vs (10) UCF | C10: =Master_Results!D8 -> 0 | D10: =Raman!D10 -> UCLA | E10: =Porter!D10 -> UCLA | F10: =Chuck!D10 -> UCF | G10: =Shelly!D10 -> UCLA | H10: =Kim!D10 -> UCF | I10: =Tucker!D10 -> UCF
A11: Round of 64 | B11: (2) UConn vs (15) Furman | C11: =Master_Results!D9 -> 0 | D11: =Raman!D11 -> UConn | E11: =Porter!D11 -> UConn | F11: =Chuck!D11 -> UConn | G11: =Shelly!D11 -> UConn | H11: =Kim!D11 -> UConn | I11: =Tucker!D11 -> UConn
A12: Round of 64 | B12: (1) Florida vs (16) Prairie View A&M | C12: =Master_Results!D10 -> 0 | D12: =Raman!D12 -> Florida | E12: =Porter!D12 -> Florida | F12: =Chuck!D12 -> Florida | G12: =Shelly!D12 -> Florida | H12: =Kim!D12 -> Florida | I12: =Tucker!D12 -> Florida
A13: Round of 64 | B13: (8) Clemson vs (9) Iowa | C13: =Master_Results!D11 -> 0 | D13: =Raman!D13 -> Clemson | E13: =Porter!D13 -> Clemson | F13: =Chuck!D13 -> Iowa | G13: =Shelly!D13 -> Clemson | H13: =Kim!D13 -> Iowa | I13: =Tucker!D13 -> Iowa
A14: Round of 64 | B14: (5) Vandy vs (12) McNeese | C14: =Master_Results!D12 -> 0 | D14: =Raman!D14 -> Vandy | E14: =Porter!D14 -> Vandy | F14: =Chuck!D14 -> Vandy | G14: =Shelly!D14 -> Vandy | H14: =Kim!D14 -> Vandy | I14: =Tucker!D14 -> Vandy
A15: Round of 64 | B15: (4) Nebraska vs (13) Troy | C15: =Master_Results!D13 -> 0 | D15: =Raman!D15 -> Nebraska | E15: =Porter!D15 -> Nebraska | F15: =Chuck!D15 -> Nebraska | G15: =Shelly!D15 -> Nebraska | H15: =Kim!D15 -> Nebraska | I15: =Tucker!D15 -> Nebraska
... A35: Round of 64 | B35: (2) Iowa St vs (15) Tenn St | C35: =Master_Results!D33 -> 0 | D35: =Raman!D35 -> Iowa State | E35: =Porter!D35 -> Iowa State | F35: =Chuck!D35 -> Iowa State | G35: =Shelly!D35 -> Iowa State | H35: =Kim!D35 -> Iowa State | I35: =Tucker!D35 -> Iowa
A36: ▸ ROUND OF 32
A37: Round of 32 | B37: Winner Game 1 & 2 | C37: =Master_Results!D34 -> 0 | D37: =Raman!D37 -> Duke | E37: =Porter!D37 -> Duke | F37: =Chuck!D37 -> Duke | G37: =Shelly!D37 -> Duke | H37: =Kim!D37 -> Duke | I37: =Tucker!D37 -> Duke
A38: Round of 32 | B38: Winner Game 3 & 4 | C38: =Master_Results!D35 -> 0 | D38: =Raman!D38 -> St. John | E38: =Porter!D38 -> Kansas | F38: =Chuck!D38 -> Kansas | G38: =Shelly!D38 -> Kansas | H38: =Kim!D38 -> Kansas | I38: =Tucker!D38 -> Kansas
A39: Round of 32 | B39: Winner Game 5 & 6 | C39: =Master_Results!D36 -> 0 | D39: =Raman!D39 -> Mich St | E39: =Porter!D39 -> Mich St | F39: =Chuck!D39 -> Mich St | G39: =Shelly!D39 -> Michigan St | H39: =Kim!D39 -> Mich St | I39: =Tucker!D39 -> Mich St
A40: Round of 32 | B40: Winner Game 7 & 8 | C40: =Master_Results!D37 -> 0 | D40: =Raman!D40 -> UCLA | E40: =Porter!D40 -> UConn | F40: =Chuck!D40 -> UConn | G40: =Shelly!D40 -> UConn | H40: =Kim!D40 -> UConn | I40: =Tucker!D40 -> UConn
A41: Round of 32 | B41: Winner Game 9 & 10 | C41: =Master_Results!D38 -> 0 | D41: =Raman!D41 -> Florida | E41: =Porter!D41 -> Florida | F41: =Chuck!D41 -> Florida | G41: =Shelly!D41 -> Florida | H41: =Kim!D41 -> Florida | I41: =Tucker!D41 -> Florida
A42: Round of 32 | B42: Winner Game 11 & 12 | C42: =Master_Results!D39 -> 0 | D42: =Raman!D42 -> Vandy | E42: =Porter!D42 -> Vandy | F42: =Chuck!D42 -> Vandy | G42: =Shelly!D42 -> Nebraska | H42: =Kim!D42 -> Nebraska | I42: =Tucker!D42 -> Nebraska
A43: Round of 32 | B43: Winner Game 13 & 14 | C43: =Master_Results!D40 -> 0 | D43: =Raman!D43 -> North Carolina | E43: =Porter!D43 -> Nebraska | F43: =Chuck!D43 -> Nebraska | G43: =Shelly!D43 -> VCU | H43: =Kim!D43 -> North Carolina | I43: =Tucker!D43 -> Illinois
A44: Round of 32 | B44: Winner Game 15 & 16 | C44: =Master_Results!D41 -> 0 | D44: =Raman!D44 -> Houston | E44: =Porter!D44 -> Houston | F44: =Chuck!D44 -> Houston | G44: =Shelly!D44 -> Houston | H44: =Kim!D44 -> Houston | I44: =Tucker!D44 -> Houston
A45: Round of 32 | B45: Winner Game 17 & 18 | C45: =Master_Results!D42 -> 0 | D45: =Raman!D45 -> Arizona | E45: =Porter!D45 -> Arizona | F45: =Chuck!D45 -> Arizona | G45: =Shelly!D45 -> Arizona | H45: =Kim!D45 -> Arizona | I45: =Tucker!D45 -> Arizona
A46: Round of 32 | B46: Winner Game 19 & 20 | C46: =Master_Results!D43 -> 0 | D46: =Raman!D46 -> Arkansas | E46: =Porter!D46 -> Arkansas | F46: =Chuck!D46 -> Arkansas | G46: =Shelly!D46 -> Arkansas | H46: =Kim!D46 -> Arkansas | I46: =Tucker!D46 -> Wisconsin
A47: Round of 32 | B47: Winner Game 21 & 22 | C47: =Master_Results!D44 -> 0 | D47: =Raman!D47 -> Gonzaga | E47: =Porter!D47 -> Gonzaga | F47: =Chuck!D47 -> Gonzaga | G47: =Shelly!D47 -> BYU | H47: =Kim!D47 -> BYU | I47: =Tucker!D47 -> BYU
A48: Round of 32 | B48: Winner Game 23 & 24 | C48: =Master_Results!D45 -> 0 | D48: =Raman!D48 -> Purdue | E48: =Porter!D48 -> Purdue | F48: =Chuck!D48 -> Purdue | G48: =Shelly!D48 -> Purdue | H48: =Kim!D48 -> Purdue | I48: =Tucker!D48 -> Purdue
... A52: Round of 32 | B52: Winner Game 31 & 32 | C52: =Master_Results!D49 -> 0 | D52: =Raman!D52 -> Iowa | E52: =Porter!D52 -> Iowa State | F52: =Chuck!D52 -> Iowa State | G52: =Shelly!D52 -> Kentucky | H52: =Kim!D52 -> Iowa State | I52: =Tucker!D52 -> Iowa
A53: ▸ SWEET 16
A54: Sweet 16 | B54: Winner Game 1 & 2 | C54: =Master_Results!D50 -> 0 | D54: =Raman!D54 -> Duke | E54: =Porter!D54 -> Duke | F54: =Chuck!D54 -> Duke | G54: =Shelly!D54 -> Duke | H54: =Kim!D54 -> Duke | I54: =Tucker!D54 -> Duke
A55: Sweet 16 | B55: Winner Game 3 & 4 | C55: =Master_Results!D51 -> 0 | D55: =Raman!D55 -> UCLA | E55: =Porter!D55 -> UConn | F55: =Chuck!D55 -> UConn | G55: =Shelly!D55 -> Michigan St | H55: =Kim!D55 -> UConn | I55: =Tucker!D55 -> UConn
A56: Sweet 16 | B56: Winner Game 5 & 6 | C56: =Master_Results!D52 -> 0 | D56: =Raman!D56 -> Vandy | E56: =Porter!D56 -> Florida | F56: =Chuck!D56 -> Florida | G56: =Shelly!D56 -> Florida | H56: =Kim!D56 -> North Carolina | I56: =Tucker!D56 -> Florida
A57: Sweet 16 | B57: Winner Game 7 & 8 | C57: =Master_Results!D53 -> 0 | D57: =Raman!D57 -> Houston | E57: =Porter!D57 -> Houston | F57: =Chuck!D57 -> Houston | G57: =Shelly!D57 -> Houston | H57: =Kim!D57 -> Houston | I57: =Tucker!D57 -> Illinois
A58: Sweet 16 | B58: Winner Game 9 & 10 | C58: =Master_Results!D54 -> 0 | D58: =Raman!D58 -> Arizona | E58: =Porter!D58 -> Arizona | F58: =Chuck!D58 -> Arizona | G58: =Shelly!D58 -> Arizona | H58: =Kim!D58 -> Arizona | I58: =Tucker!D58 -> Arizona
A59: Sweet 16 | B59: Winner Game 11 & 12 | C59: =Master_Results!D55 -> 0 | D59: =Raman!D59 -> Purdue | E59: =Porter!D59 -> Purdue | F59: =Chuck!D59 -> Gonzaga | G59: =Shelly!D59 -> Purdue | H59: =Kim!D59 -> Purdue | I59: =Tucker!D59 -> Purdue
A60: Sweet 16 | B60: Winner Game 13 & 14 | C60: =Master_Results!D56 -> 0 | D60: =Raman!D60 -> Michigan | E60: =Porter!D60 -> Michigan | F60: =Chuck!D60 -> Michigan | G60: =Shelly!D60 -> Michigan | H60: =Kim!D60 -> Michigan | I60: =Tucker!D60 -> Michigan
A61: Sweet 16 | B61: Winner Game 15 & 16 | C61: =Master_Results!D57 -> 0 | D61: =Raman!D61 -> Iowa | E61: =Porter!D61 -> Alabama | F61: =Chuck!D61 -> Alabama | G61: =Shelly!D61 -> Alabama | H61: =Kim!D61 -> Alabama | I61: =Tucker!D61 -> Virginia
A62: ▸ ELITE 8
...

Sheet ESPN_Data
A1: 📡 ESPN Live Data — Refresh via Data ▸ Refresh All
A2: Team 1 | B2: Team 2 | C2: Winner
