Workbook

Sheet 📊 Comparison
A1: 📊 HEAD-TO-HEAD PICK COMPARISON — All Participants
A2: Round | B2: Matchup | C2: Actual Winner | D2: Raman | E2: Porter | F2: Chuck | G2: Shelly | H2: Kim | I2: Tucker
A3: ▸ ROUND OF 64
A4: Round of 64 | B4: (1) Duke vs (16) Siena | C4: =Master_Results!D2 | D4: =Raman!D4 | E4: =Porter!D4 | F4: =Chuck!D4 | G4: =Shelly!D4 | H4: =Kim!D4 | I4: =Tucker!D4
A5: Round of 64 | B5: (8) Ohio St vs (9) TCU | C5: =Master_Results!D3 | D5: =Raman!D5 | E5: =Porter!D5 | F5: =Chuck!D5 | G5: =Shelly!D5 | H5: =Kim!D5 | I5: =Tucker!D5
A6: Round of 64 | B6: (5) St. John's vs (12) Northern Iowa | C6: =Master_Results!D4 | D6: =Raman!D6 | E6: =Porter!D6 | F6: =Chuck!D6 | G6: =Shelly!D6 | H6: =Kim!D6 | I6: =Tucker!D6
A7: Round of 64 | B7: (4) Kansas vs (13) Cal Baptist | C7: =Master_Results!D5 | D7: =Raman!D7 | E7: =Porter!D7 | F7: =Chuck!D7 | G7: =Shelly!D7 | H7: =Kim!D7 | I7: =Tucker!D7
A8: Round of 64 | B8: (6) Louisville vs (11) South Florida | C8: =Master_Results!D6 | D8: =Raman!D8 | E8: =Porter!D8 | F8: =Chuck!D8 | G8: =Shelly!D8 | H8: =Kim!D8 | I8: =Tucker!D8
A9: Round of 64 | B9: (3) Michigan St vs (14) ND State | C9: =Master_Results!D7 | D9: =Raman!D9 | E9: =Porter!D9 | F9: =Chuck!D9 | G9: =Shelly!D9 | H9: =Kim!D9 | I9: =Tucker!D9
A10: Round of 64 | B10: (7) UCLA vs (10) UCF | C10: =Master_Results!D8 | D10: =Raman!D10 | E10: =Porter!D10 | F10: =Chuck!D10 | G10: =Shelly!D10 | H10: =Kim!D10 | I10: =Tucker!D10
A11: Round of 64 | B11: (2) UConn vs (15) Furman | C11: =Master_Results!D9 | D11: =Raman!D11 | E11: =Porter!D11 | F11: =Chuck!D11 | G11: =Shelly!D11 | H11: =Kim!D11 | I11: =Tucker!D11
A12: Round of 64 | B12: (1) Florida vs (16) Prairie View A&M | C12: =Master_Results!D10 | D12: =Raman!D12 | E12: =Porter!D12 | F12: =Chuck!D12 | G12: =Shelly!D12 | H12: =Kim!D12 | I12: =Tucker!D12
A13: Round of 64 | B13: (8) Clemson vs (9) Iowa | C13: =Master_Results!D11 | D13: =Raman!D13 | E13: =Porter!D13 | F13: =Chuck!D13 | G13: =Shelly!D13 | H13: =Kim!D13 | I13: =Tucker!D13
A14: Round of 64 | B14: (5) Vandy vs (12) McNeese | C14: =Master_Results!D12 | D14: =Raman!D14 | E14: =Porter!D14 | F14: =Chuck!D14 | G14: =Shelly!D14 | H14: =Kim!D14 | I14: =Tucker!D14
A15: Round of 64 | B15: (4) Nebraska vs (13) Troy | C15: =Master_Results!D13 | D15: =Raman!D15 | E15: =Porter!D15 | F15: =Chuck!D15 | G15: =Shelly!D15 | H15: =Kim!D15 | I15: =Tucker!D15
... A35: Round of 64 | B35: (2) Iowa St vs (15) Tenn St | C35: =Master_Results!D33 | D35: =Raman!D35 | E35: =Porter!D35 | F35: =Chuck!D35 | G35: =Shelly!D35 | H35: =Kim!D35 | I35: =Tucker!D35
A36: ▸ ROUND OF 32
A37: Round of 32 | B37: Winner Game 1 & 2 | C37: =Master_Results!D34 | D37: =Raman!D37 | E37: =Porter!D37 | F37: =Chuck!D37 | G37: =Shelly!D37 | H37: =Kim!D37 | I37: =Tucker!D37
A38: Round of 32 | B38: Winner Game 3 & 4 | C38: =Master_Results!D35 | D38: =Raman!D38 | E38: =Porter!D38 | F38: =Chuck!D38 | G38: =Shelly!D38 | H38: =Kim!D38 | I38: =Tucker!D38
A39: Round of 32 | B39: Winner Game 5 & 6 | C39: =Master_Results!D36 | D39: =Raman!D39 | E39: =Porter!D39 | F39: =Chuck!D39 | G39: =Shelly!D39 | H39: =Kim!D39 | I39: =Tucker!D39
A40: Round of 32 | B40: Winner Game 7 & 8 | C40: =Master_Results!D37 | D40: =Raman!D40 | E40: =Porter!D40 | F40: =Chuck!D40 | G40: =Shelly!D40 | H40: =Kim!D40 | I40: =Tucker!D40
A41: Round of 32 | B41: Winner Game 9 & 10 | C41: =Master_Results!D38 | D41: =Raman!D41 | E41: =Porter!D41 | F41: =Chuck!D41 | G41: =Shelly!D41 | H41: =Kim!D41 | I41: =Tucker!D41
A42: Round of 32 | B42: Winner Game 11 & 12 | C42: =Master_Results!D39 | D42: =Raman!D42 | E42: =Porter!D42 | F42: =Chuck!D42 | G42: =Shelly!D42 | H42: =Kim!D42 | I42: =Tucker!D42
A43: Round of 32 | B43: Winner Game 13 & 14 | C43: =Master_Results!D40 | D43: =Raman!D43 | E43: =Porter!D43 | F43: =Chuck!D43 | G43: =Shelly!D43 | H43: =Kim!D43 | I43: =Tucker!D43
A44: Round of 32 | B44: Winner Game 15 & 16 | C44: =Master_Results!D41 | D44: =Raman!D44 | E44: =Porter!D44 | F44: =Chuck!D44 | G44: =Shelly!D44 | H44: =Kim!D44 | I44: =Tucker!D44
A45: Round of 32 | B45: Winner Game 17 & 18 | C45: =Master_Results!D42 | D45: =Raman!D45 | E45: =Porter!D45 | F45: =Chuck!D45 | G45: =Shelly!D45 | H45: =Kim!D45 | I45: =Tucker!D45
A46: Round of 32 | B46: Winner Game 19 & 20 | C46: =Master_Results!D43 | D46: =Raman!D46 | E46: =Porter!D46 | F46: =Chuck!D46 | G46: =Shelly!D46 | H46: =Kim!D46 | I46: =Tucker!D46
A47: Round of 32 | B47: Winner Game 21 & 22 | C47: =Master_Results!D44 | D47: =Raman!D47 | E47: =Porter!D47 | F47: =Chuck!D47 | G47: =Shelly!D47 | H47: =Kim!D47 | I47: =Tucker!D47
A48: Round of 32 | B48: Winner Game 23 & 24 | C48: =Master_Results!D45 | D48: =Raman!D48 | E48: =Porter!D48 | F48: =Chuck!D48 | G48: =Shelly!D48 | H48: =Kim!D48 | I48: =Tucker!D48
... A52: Round of 32 | B52: Winner Game 31 & 32 | C52: =Master_Results!D49 | D52: =Raman!D52 | E52: =Porter!D52 | F52: =Chuck!D52 | G52: =Shelly!D52 | H52: =Kim!D52 | I52: =Tucker!D52
A53: ▸ SWEET 16
A54: Sweet 16 | B54: Winner Game 1 & 2 | C54: =Master_Results!D50 | D54: =Raman!D54 | E54: =Porter!D54 | F54: =Chuck!D54 | G54: =Shelly!D54 | H54: =Kim!D54 | I54: =Tucker!D54
A55: Sweet 16 | B55: Winner Game 3 & 4 | C55: =Master_Results!D51 | D55: =Raman!D55 | E55: =Porter!D55 | F55: =Chuck!D55 | G55: =Shelly!D55 | H55: =Kim!D55 | I55: =Tucker!D55
A56: Sweet 16 | B56: Winner Game 5 & 6 | C56: =Master_Results!D52 | D56: =Raman!D56 | E56: =Porter!D56 | F56: =Chuck!D56 | G56: =Shelly!D56 | H56: =Kim!D56 | I56: =Tucker!D56
A57: Sweet 16 | B57: Winner Game 7 & 8 | C57: =Master_Results!D53 | D57: =Raman!D57 | E57: =Porter!D57 | F57: =Chuck!D57 | G57: =Shelly!D57 | H57: =Kim!D57 | I57: =Tucker!D57
A58: Sweet 16 | B58: Winner Game 9 & 10 | C58: =Master_Results!D54 | D58: =Raman!D58 | E58: =Porter!D58 | F58: =Chuck!D58 | G58: =Shelly!D58 | H58: =Kim!D58 | I58: =Tucker!D58
A59: Sweet 16 | B59: Winner Game 11 & 12 | C59: =Master_Results!D55 | D59: =Raman!D59 | E59: =Porter!D59 | F59: =Chuck!D59 | G59: =Shelly!D59 | H59: =Kim!D59 | I59: =Tucker!D59
A60: Sweet 16 | B60: Winner Game 13 & 14 | C60: =Master_Results!D56 | D60: =Raman!D60 | E60: =Porter!D60 | F60: =Chuck!D60 | G60: =Shelly!D60 | H60: =Kim!D60 | I60: =Tucker!D60
A61: Sweet 16 | B61: Winner Game 15 & 16 | C61: =Master_Results!D57 | D61: =Raman!D61 | E61: =Porter!D61 | F61: =Chuck!D61 | G61: =Shelly!D61 | H61: =Kim!D61 | I61: =Tucker!D61
A62: ▸ ELITE 8
...

Sheet Tucker
A1: 🏀 TUCKER'S 2026 MARCH MADNESS BRACKET
A2: Round | B2: Game ID | C2: Matchup | D2: Pick | E2: Pts Value | F2: Result | G2: Pts Earned
A3: ▸ ROUND OF 64 • 1 pt each
A4: Round of 64 | B4: R64_G1 | C4: (1) Duke vs (16) Siena | D4: Duke | E4: 1 | F4: =IF(Master_Results!$D$4="","",IF(D4=Master_Results!$D$4,1,0)) | G4: =IF(F4="","",E4*F4)
A5: Round of 64 | B5: R64_G2 | C5: (8) Ohio St vs (9) TCU | D5: TCU | E5: 1 | F5: =IF(Master_Results!$D$5="","",IF(D5=Master_Results!$D$5,1,0)) | G5: =IF(F5="","",E5*F5)
A6: Round of 64 | B6: R64_G3 | C6: (5) St. John's vs (12) Northern Iowa | D6: St. John's | E6: 1 | F6: =IF(Master_Results!$D$6="","",IF(D6=Master_Results!$D$6,1,0)) | G6: =IF(F6="","",E6*F6)
A7: Round of 64 | B7: R64_G4 | C7: (4) Kansas vs (13) Cal Baptist | D7: Kansas | E7: 1 | F7: =IF(Master_Results!$D$7="","",IF(D7=Master_Results!$D$7,1,0)) | G7: =IF(F7="","",E7*F7)
A8: Round of 64 | B8: R64_G5 | C8: (6) Louisville vs (11) South Florida | D8: South Florida | E8: 1 | F8: =IF(Master_Results!$D$8="","",IF(D8=Master_Results!$D$8,1,0)) | G8: =IF(F8="","",E8*F8)
A9: Round of 64 | B9: R64_G6 | C9: (3) Michigan St vs (14) ND State | D9: Mich St | E9: 1 | F9: =IF(Master_Results!$D$9="","",IF(D9=Master_Results!$D$9,1,0)) | G9: =IF(F9="","",E9*F9)
A10: Round of 64 | B10: R64_G7 | C10: (7) UCLA vs (10) UCF | D10: UCF | E10: 1 | F10: =IF(Master_Results!$D$10="","",IF(D10=Master_Results!$D$10,1,0)) | G10: =IF(F10="","",E10*F10)
A11: Round of 64 | B11: R64_G8 | C11: (2) UConn vs (15) Furman | D11: UConn | E11: 1 | F11: =IF(Master_Results!$D$11="","",IF(D11=Master_Results!$D$11,1,0)) | G11: =IF(F11="","",E11*F11)
A12: Round of 64 | B12: R64_G9 | C12: (1) Florida vs (16) Prairie View A&M | D12: Florida | E12: 1 | F12: =IF(Master_Results!$D$12="","",IF(D12=Master_Results!$D$12,1,0)) | G12: =IF(F12="","",E12*F12)
A13: Round of 64 | B13: R64_G10 | C13: (8) Clemson vs (9) Iowa | D13: Iowa | E13: 1 | F13: =IF(Master_Results!$D$13="","",IF(D13=Master_Results!$D$13,1,0)) | G13: =IF(F13="","",E13*F13)
A14: Round of 64 | B14: R64_G11 | C14: (5) Vandy vs (12) McNeese | D14: Vandy | E14: 1 | F14: =IF(Master_Results!$D$14="","",IF(D14=Master_Results!$D$14,1,0)) | G14: =IF(F14="","",E14*F14)
A15: Round of 64 | B15: R64_G12 | C15: (4) Nebraska vs (13) Troy | D15: Nebraska | E15: 1 | F15: =IF(Master_Results!$D$15="","",IF(D15=Master_Results!$D$15,1,0)) | G15: =IF(F15="","",E15*F15)
A16: Round of 64 | B16: R64_G13 | C16: (6) North Carolina vs (11) VCU | D16: VCU | E16: 1 | F16: =IF(Master_Results!$D$16="","",IF(D16=Master_Results!$D$16,1,0)) | G16: =IF(F16="","",E16*F16)
A17: Round of 64 | B17: R64_G14 | C17: (3) Illinois vs (14) Penn | D17: Illinois | E17: 1 | F17: =IF(Master_Results!$D$17="","",IF(D17=Master_Results!$D$17,1,0)) | G17: =IF(F17="","",E17*F17)
A18: Round of 64 | B18: R64_G15 | C18: (7) St. Mary's vs (10) Texas A&M | D18: St. Mary | E18: 1 | F18: =IF(Master_Results!$D$18="","",IF(D18=Master_Results!$D$18,1,0)) | G18: =IF(F18="","",E18*F18)
A19: Round of 64 | B19: R64_G16 | C19: (2) Houston vs (15) Idaho | D19: Houston | E19: 1 | F19: =IF(Master_Results!$D$19="","",IF(D19=Master_Results!$D$19,1,0)) | G19: =IF(F19="","",E19*F19)
A20: Round of 64 | B20: R64_G17 | C20: (1) Arizona vs (16) Long Island | D20: Arizona | E20: 1 | F20: =IF(Master_Results!$D$20="","",IF(D20=Master_Results!$D$20,1,0)) | G20: =IF(F20="","",E20*F20)
A21: Round of 64 | B21: R64_G18 | C21: (8) Villanova vs (9) Utah St | D21: Villanova | E21: 1 | F21: =IF(Master_Results!$D$21="","",IF(D21=Master_Results!$D$21,1,0)) | G21: =IF(F21="","",E21*F21)
A22: Round of 64 | B22: R64_G19 | C22: (5) Wisconsin vs (12) High Point | D22: Wisconsin | E22: 1 | F22: =IF(Master_Results!$D$22="","",IF(D22=Master_Results!$D$22,1,0)) | G22: =IF(F22="","",E22*F22)
A23: Round of 64 | B23: R64_G20 | C23: (4) Arkansas vs (13) Hawai'i | D23: Arkansas | E23: 1 | F23: =IF(Master_Results!$D$23="","",IF(D23=Master_Results!$D$23,1,0)) | G23: =IF(F23="","",E23*F23)
A24: Round of 64 | B24: R64_G21 | C24: (6) BYU vs (11) Texas | D24: BYU | E24: 1 | F24: =IF(Master_Results!$D$24="","",IF(D24=Master_Results!$D$24,1,0)) | G24: =IF(F24="","",E24*F24)
A25: Round of 64 | B25: R64_G22 | C25: (3) Gonzaga vs (14) Kennesaw St | D25: Gonzaga | E25: 1 | F25: =IF(Master_Results!$D$25="","",IF(D25=Master_Results!$D$25,1,0)) | G25: =IF(F25="","",E25*F25)
A26: Round of 64 | B26: R64_G23 | C26: (7) Miami (FL) vs (10) Missouri | D26: Miami | E26: 1 | F26: =IF(Master_Results!$D$26="","",IF(D26=Master_Results!$D$26,1,0)) | G26: =IF(F26="","",E26*F26)
A27: Round of 64 | B27: R64_G24 | C27: (2) Purdue vs (15) Queens | D27: Purdue | E27: 1 | F27: =IF(Master_Results!$D$27="","",IF(D27=Master_Results!$D$27,1,0)) | G27: =IF(F27="","",E27*F27)
A28: Round of 64 | B28: R64_G25 | C28: (1) Michigan vs (16) Howard | D28: Michigan | E28: 1 | F28: =IF(Master_Results!$D$28="","",IF(D28=Master_Results!$D$28,1,0)) | G28: =IF(F28="","",E28*F28)
A29: Round of 64 | B29: R64_G26 | C29: (8) Georgia vs (9) St. Louis | D29: Georgia | E29: 1 | F29: =IF(Master_Results!$D$29="","",IF(D29=Master_Results!$D$29,1,0)) | G29: =IF(F29="","",E29*F29)
A30: Round of 64 | B30: R64_G27 | C30: (5) Texas Tech vs (12) Akron | D30: Texas Tech | E30: 1 | F30: =IF(Master_Results!$D$30="","",IF(D30=Master_Results!$D$30,1,0)) | G30: =IF(F30="","",E30*F30)
A31: Round of 64 | B31: R64_G28 | C31: (4) Alabama vs (13) Hofstra | D31: Alabama | E31: 1 | F31: =IF(Master_Results!$D$31="","",IF(D31=Master_Results!$D$31,1,0)) | G31: =IF(F31="","",E31*F31)
A32: Round of 64 | B32: R64_G29 | C32: (6) Tennessee vs (11) Miami (OH) | D32: Tennessee | E32: 1 | F32: =IF(Master_Results!$D$32="","",IF(D32=Master_Results!$D$32,1,0)) | G32: =IF(F32="","",E32*F32)
A33: Round of 64 | B33: R64_G30 | C33: (3) Virginia vs (14) Wright St | D33: Virginia | E33: 1 | F33: =IF(Master_Results!$D$33="","",IF(D33=Master_Results!$D$33,1,0)) | G33: =IF(F33="","",E33*F33)
A34: Round of 64 | B34: R64_G31 | C34: (7) Kentucky vs (10) Santa Clara | D34: Kentucky | E34: 1 | F34: =IF(Master_Results!$D$34="","",IF(D34=Master_Results!$D$34,1,0)) | G34: =IF(F34="","",E34*F34)
A35: Round of 64 | B35: R64_G32 | C35: (2) Iowa St vs (15) Tenn St | D35: Iowa | E35: 1 | F35: =IF(Master_Results!$D$35="","",IF(D35=Master_Results!$D$35,1,0)) | G35: =IF(F35="","",E35*F35)
A36: ▸ ROUND OF 32 • 2 pts each
A37: Round of 32 | B37: Rou_G1 | C37: Winner Game 1 & 2 | D37: Duke | E37: 2 | F37: =IF(Master_Results!$D$37="","",IF(D37=Master_Results!$D$37,1,0)) | G37: =IF(F37="","",E37*F37)
A38: Round of 32 | B38: Rou_G2 | C38: Winner Game 3 & 4 | D38: Kansas | E38: 2 | F38: =IF(Master_Results!$D$38="","",IF(D38=Master_Results!$D$38,1,0)) | G38: =IF(F38="","",E38*F38)
A39: Round of 32 | B39: Rou_G3 | C39: Winner Game 5 & 6 | D39: Mich St | E39: 2 | F39: =IF(Master_Results!$D$39="","",IF(D39=Master_Results!$D$39,1,0)) | G39: =IF(F39="","",E39*F39)
A40: Round of 32 | B40: Rou_G4 | C40: Winner Game 7 & 8 | D40: UConn | E40: 2 | F40: =IF(Master_Results!$D$40="","",IF(D40=Master_Results!$D$40,1,0)) | G40: =IF(F40="","",E40*F40)
...

Sheet Kim
A1: 🏀 KIM'S 2026 MARCH MADNESS BRACKET
A2: Round | B2: Game ID | C2: Matchup | D2: Pick | E2: Pts Value | F2: Result | G2: Pts Earned
A3: ▸ ROUND OF 64 • 1 pt each
A4: Round of 64 | B4: R64_G1 | C4: (1) Duke vs (16) Siena | D4: Duke | E4: 1 | F4: =IF(Master_Results!$D$4="","",IF(D4=Master_Results!$D$4,1,0)) | G4: =IF(F4="","",E4*F4)
A5: Round of 64 | B5: R64_G2 | C5: (8) Ohio St vs (9) TCU | D5: TCU | E5: 1 | F5: =IF(Master_Results!$D$5="","",IF(D5=Master_Results!$D$5,1,0)) | G5: =IF(F5="","",E5*F5)
A6: Round of 64 | B6: R64_G3 | C6: (5) St. John's vs (12) Northern Iowa | D6: St. John | E6: 1 | F6: =IF(Master_Results!$D$6="","",IF(D6=Master_Results!$D$6,1,0)) | G6: =IF(F6="","",E6*F6)
A7: Round of 64 | B7: R64_G4 | C7: (4) Kansas vs (13) Cal Baptist | D7: Kansas | E7: 1 | F7: =IF(Master_Results!$D$7="","",IF(D7=Master_Results!$D$7,1,0)) | G7: =IF(F7="","",E7*F7)
A8: Round of 64 | B8: R64_G5 | C8: (6) Louisville vs (11) South Florida | D8: Louisville | E8: 1 | F8: =IF(Master_Results!$D$8="","",IF(D8=Master_Results!$D$8,1,0)) | G8: =IF(F8="","",E8*F8)
A9: Round of 64 | B9: R64_G6 | C9: (3) Michigan St vs (14) ND State | D9: Mich St | E9: 1 | F9: =IF(Master_Results!$D$9="","",IF(D9=Master_Results!$D$9,1,0)) | G9: =IF(F9="","",E9*F9)
A10: Round of 64 | B10: R64_G7 | C10: (7) UCLA vs (10) UCF | D10: UCF | E10: 1 | F10: =IF(Master_Results!$D$10="","",IF(D10=Master_Results!$D$10,1,0)) | G10: =IF(F10="","",E10*F10)
A11: Round of 64 | B11: R64_G8 | C11: (2) UConn vs (15) Furman | D11: UConn | E11: 1 | F11: =IF(Master_Results!$D$11="","",IF(D11=Master_Results!$D$11,1,0)) | G11: =IF(F11="","",E11*F11)
A12: Round of 64 | B12: R64_G9 | C12: (1) Florida vs (16) Prairie View A&M | D12: Florida | E12: 1 | F12: =IF(Master_Results!$D$12="","",IF(D12=Master_Results!$D$12,1,0)) | G12: =IF(F12="","",E12*F12)
A13: Round of 64 | B13: R64_G10 | C13: (8) Clemson vs (9) Iowa | D13: Iowa | E13: 1 | F13: =IF(Master_Results!$D$13="","",IF(D13=Master_Results!$D$13,1,0)) | G13: =IF(F13="","",E13*F13)
A14: Round of 64 | B14: R64_G11 | C14: (5) Vandy vs (12) McNeese | D14: Vandy | E14: 1 | F14: =IF(Master_Results!$D$14="","",IF(D14=Master_Results!$D$14,1,0)) | G14: =IF(F14="","",E14*F14)
A15: Round of 64 | B15: R64_G12 | C15: (4) Nebraska vs (13) Troy | D15: Nebraska | E15: 1 | F15: =IF(Master_Results!$D$15="","",IF(D15=Master_Results!$D$15,1,0)) | G15: =IF(F15="","",E15*F15)
A16: Round of 64 | B16: R64_G13 | C16: (6) North Carolina vs (11) VCU | D16: North Carolina | E16: 1 | F16: =IF(Master_Results!$D$16="","",IF(D16=Master_Results!$D$16,1,0)) | G16: =IF(F16="","",E16*F16)
A17: Round of 64 | B17: R64_G14 | C17: (3) Illinois vs (14) Penn | D17: Illinois | E17: 1 | F17: =IF(Master_Results!$D$17="","",IF(D17=Master_Results!$D$17,1,0)) | G17: =IF(F17="","",E17*F17)
A18: Round of 64 | B18: R64_G15 | C18: (7) St. Mary's vs (10) Texas A&M | D18: Texas A&M | E18: 1 | F18: =IF(Master_Results!$D$18="","",IF(D18=Master_Results!$D$18,1,0)) | G18: =IF(F18="","",E18*F18)
A19: Round of 64 | B19: R64_G16 | C19: (2) Houston vs (15) Idaho | D19: Houston | E19: 1 | F19: =IF(Master_Results!$D$19="","",IF(D19=Master_Results!$D$19,1,0)) | G19: =IF(F19="","",E19*F19)
A20: Round of 64 | B20: R64_G17 | C20: (1) Arizona vs (16) Long Island | D20: Arizona | E20: 1 | F20: =IF(Master_Results!$D$20="","",IF(D20=Master_Results!$D$20,1,0)) | G20: =IF(F20="","",E20*F20)
A21: Round of 64 | B21: R64_G18 | C21: (8) Villanova vs (9) Utah St | D21: Villanova | E21: 1 | F21: =IF(Master_Results!$D$21="","",IF(D21=Master_Results!$D$21,1,0)) | G21: =IF(F21="","",E21*F21)
A22: Round of 64 | B22: R64_G19 | C22: (5) Wisconsin vs (12) High Point | D22: Wisconsin | E22: 1 | F22: =IF(Master_Results!$D$22="","",IF(D22=Master_Results!$D$22,1,0)) | G22: =IF(F22="","",E22*F22)
A23: Round of 64 | B23: R64_G20 | C23: (4) Arkansas vs (13) Hawai'i | D23: Arkansas | E23: 1 | F23: =IF(Master_Results!$D$23="","",IF(D23=Master_Results!$D$23,1,0)) | G23: =IF(F23="","",E23*F23)
A24: Round of 64 | B24: R64_G21 | C24: (6) BYU vs (11) Texas | D24: BYU | E24: 1 | F24: =IF(Master_Results!$D$24="","",IF(D24=Master_Results!$D$24,1,0)) | G24: =IF(F24="","",E24*F24)
A25: Round of 64 | B25: R64_G22 | C25: (3) Gonzaga vs (14) Kennesaw St | D25: Gonzaga | E25: 1 | F25: =IF(Master_Results!$D$25="","",IF(D25=Master_Results!$D$25,1,0)) | G25: =IF(F25="","",E25*F25)
A26: Round of 64 | B26: R64_G23 | C26: (7) Miami (FL) vs (10) Missouri | D26: Missouri | E26: 1 | F26: =IF(Master_Results!$D$26="","",IF(D26=Master_Results!$D$26,1,0)) | G26: =IF(F26="","",E26*F26)
A27: Round of 64 | B27: R64_G24 | C27: (2) Purdue vs (15) Queens | D27: Purdue | E27: 1 | F27: =IF(Master_Results!$D$27="","",IF(D27=Master_Results!$D$27,1,0)) | G27: =IF(F27="","",E27*F27)
A28: Round of 64 | B28: R64_G25 | C28: (1) Michigan vs (16) Howard | D28: Michigan | E28: 1 | F28: =IF(Master_Results!$D$28="","",IF(D28=Master_Results!$D$28,1,0)) | G28: =IF(F28="","",E28*F28)
A29: Round of 64 | B29: R64_G26 | C29: (8) Georgia vs (9) St. Louis | D29: Georgia | E29: 1 | F29: =IF(Master_Results!$D$29="","",IF(D29=Master_Results!$D$29,1,0)) | G29: =IF(F29="","",E29*F29)
A30: Round of 64 | B30: R64_G27 | C30: (5) Texas Tech vs (12) Akron | D30: Texas Tech | E30: 1 | F30: =IF(Master_Results!$D$30="","",IF(D30=Master_Results!$D$30,1,0)) | G30: =IF(F30="","",E30*F30)
A31: Round of 64 | B31: R64_G28 | C31: (4) Alabama vs (13) Hofstra | D31: Alabama | E31: 1 | F31: =IF(Master_Results!$D$31="","",IF(D31=Master_Results!$D$31,1,0)) | G31: =IF(F31="","",E31*F31)
A32: Round of 64 | B32: R64_G29 | C32: (6) Tennessee vs (11) Miami (OH) | D32: Tennessee | E32: 1 | F32: =IF(Master_Results!$D$32="","",IF(D32=Master_Results!$D$32,1,0)) | G32: =IF(F32="","",E32*F32)
A33: Round of 64 | B33: R64_G30 | C33: (3) Virginia vs (14) Wright St | D33: Virginia | E33: 1 | F33: =IF(Master_Results!$D$33="","",IF(D33=Master_Results!$D$33,1,0)) | G33: =IF(F33="","",E33*F33)
A34: Round of 64 | B34: R64_G31 | C34: (7) Kentucky vs (10) Santa Clara | D34: Kentucky | E34: 1 | F34: =IF(Master_Results!$D$34="","",IF(D34=Master_Results!$D$34,1,0)) | G34: =IF(F34="","",E34*F34)
A35: Round of 64 | B35: R64_G32 | C35: (2) Iowa St vs (15) Tenn St | D35: Iowa State | E35: 1 | F35: =IF(Master_Results!$D$35="","",IF(D35=Master_Results!$D$35,1,0)) | G35: =IF(F35="","",E35*F35)
A36: ▸ ROUND OF 32 • 2 pts each
A37: Round of 32 | B37: Rou_G1 | C37: Winner Game 1 & 2 | D37: Duke | E37: 2 | F37: =IF(Master_Results!$D$37="","",IF(D37=Master_Results!$D$37,1,0)) | G37: =IF(F37="","",E37*F37)
A38: Round of 32 | B38: Rou_G2 | C38: Winner Game 3 & 4 | D38: Kansas | E38: 2 | F38: =IF(Master_Results!$D$38="","",IF(D38=Master_Results!$D$38,1,0)) | G38: =IF(F38="","",E38*F38)
A39: Round of 32 | B39: Rou_G3 | C39: Winner Game 5 & 6 | D39: Mich St | E39: 2 | F39: =IF(Master_Results!$D$39="","",IF(D39=Master_Results!$D$39,1,0)) | G39: =IF(F39="","",E39*F39)
A40: Round of 32 | B40: Rou_G4 | C40: Winner Game 7 & 8 | D40: UConn | E40: 2 | F40: =IF(Master_Results!$D$40="","",IF(D40=Master_Results!$D$40,1,0)) | G40: =IF(F40="","",E40*F40)
...

Sheet Shelly
A1: 🏀 SHELLY'S 2026 MARCH MADNESS BRACKET
A2: Round | B2: Game ID | C2: Matchup | D2: Pick | E2: Pts Value | F2: Result | G2: Pts Earned
A3: ▸ ROUND OF 64 • 1 pt each
A4: Round of 64 | B4: R64_G1 | C4: (1) Duke vs (16) Siena | D4: Duke | E4: 1 | F4: =IF(Master_Results!$D$4="","",IF(D4=Master_Results!$D$4,1,0)) | G4: =IF(F4="","",E4*F4)
A5: Round of 64 | B5: R64_G2 | C5: (8) Ohio St vs (9) TCU | D5: TCU | E5: 1 | F5: =IF(Master_Results!$D$5="","",IF(D5=Master_Results!$D$5,1,0)) | G5: =IF(F5="","",E5*F5)
A6: Round of 64 | B6: R64_G3 | C6: (5) St. John's vs (12) Northern Iowa | D6: St. John | E6: 1 | F6: =IF(Master_Results!$D$6="","",IF(D6=Master_Results!$D$6,1,0)) | G6: =IF(F6="","",E6*F6)
A7: Round of 64 | B7: R64_G4 | C7: (4) Kansas vs (13) Cal Baptist | D7: Kansas | E7: 1 | F7: =IF(Master_Results!$D$7="","",IF(D7=Master_Results!$D$7,1,0)) | G7: =IF(F7="","",E7*F7)
A8: Round of 64 | B8: R64_G5 | C8: (6) Louisville vs (11) South Florida | D8: Louisville | E8: 1 | F8: =IF(Master_Results!$D$8="","",IF(D8=Master_Results!$D$8,1,0)) | G8: =IF(F8="","",E8*F8)
A9: Round of 64 | B9: R64_G6 | C9: (3) Michigan St vs (14) ND State | D9: Michigan St | E9: 1 | F9: =IF(Master_Results!$D$9="","",IF(D9=Master_Results!$D$9,1,0)) | G9: =IF(F9="","",E9*F9)
A10: Round of 64 | B10: R64_G7 | C10: (7) UCLA vs (10) UCF | D10: UCLA | E10: 1 | F10: =IF(Master_Results!$D$10="","",IF(D10=Master_Results!$D$10,1,0)) | G10: =IF(F10="","",E10*F10)
A11: Round of 64 | B11: R64_G8 | C11: (2) UConn vs (15) Furman | D11: UConn | E11: 1 | F11: =IF(Master_Results!$D$11="","",IF(D11=Master_Results!$D$11,1,0)) | G11: =IF(F11="","",E11*F11)
A12: Round of 64 | B12: R64_G9 | C12: (1) Florida vs (16) Prairie View A&M | D12: Florida | E12: 1 | F12: =IF(Master_Results!$D$12="","",IF(D12=Master_Results!$D$12,1,0)) | G12: =IF(F12="","",E12*F12)
A13: Round of 64 | B13: R64_G10 | C13: (8) Clemson vs (9) Iowa | D13: Clemson | E13: 1 | F13: =IF(Master_Results!$D$13="","",IF(D13=Master_Results!$D$13,1,0)) | G13: =IF(F13="","",E13*F13)
A14: Round of 64 | B14: R64_G11 | C14: (5) Vandy vs (12) McNeese | D14: Vandy | E14: 1 | F14: =IF(Master_Results!$D$14="","",IF(D14=Master_Results!$D$14,1,0)) | G14: =IF(F14="","",E14*F14)
A15: Round of 64 | B15: R64_G12 | C15: (4) Nebraska vs (13) Troy | D15: Nebraska | E15: 1 | F15: =IF(Master_Results!$D$15="","",IF(D15=Master_Results!$D$15,1,0)) | G15: =IF(F15="","",E15*F15)
A16: Round of 64 | B16: R64_G13 | C16: (6) North Carolina vs (11) VCU | D16: VCU | E16: 1 | F16: =IF(Master_Results!$D$16="","",IF(D16=Master_Results!$D$16,1,0)) | G16: =IF(F16="","",E16*F16)
A17: Round of 64 | B17: R64_G14 | C17: (3) Illinois vs (14) Penn | D17: Illinois | E17: 1 | F17: =IF(Master_Results!$D$17="","",IF(D17=Master_Results!$D$17,1,0)) | G17: =IF(F17="","",E17*F17)
A18: Round of 64 | B18: R64_G15 | C18: (7) St. Mary's vs (10) Texas A&M | D18: St. Mary's | E18: 1 | F18: =IF(Master_Results!$D$18="","",IF(D18=Master_Results!$D$18,1,0)) | G18: =IF(F18="","",E18*F18)
A19: Round of 64 | B19: R64_G16 | C19: (2) Houston vs (15) Idaho | D19: Houston | E19: 1 | F19: =IF(Master_Results!$D$19="","",IF(D19=Master_Results!$D$19,1,0)) | G19: =IF(F19="","",E19*F19)
A20: Round of 64 | B20: R64_G17 | C20: (1) Arizona vs (16) Long Island | D20: Arizona | E20: 1 | F20: =IF(Master_Results!$D$20="","",IF(D20=Master_Results!$D$20,1,0)) | G20: =IF(F20="","",E20*F20)
A21: Round of 64 | B21: R64_G18 | C21: (8) Villanova vs (9) Utah St | D21: Villanova | E21: 1 | F21: =IF(Master_Results!$D$21="","",IF(D21=Master_Results!$D$21,1,0)) | G21: =IF(F21="","",E21*F21)
A22: Round of 64 | B22: R64_G19 | C22: (5) Wisconsin vs (12) High Point | D22: Wisconsin | E22: 1 | F22: =IF(Master_Results!$D$22="","",IF(D22=Master_Results!$D$22,1,0)) | G22: =IF(F22="","",E22*F22)
A23: Round of 64 | B23: R64_G20 | C23: (4) Arkansas vs (13) Hawai'i | D23: Arkansas | E23: 1 | F23: =IF(Master_Results!$D$23="","",IF(D23=Master_Results!$D$23,1,0)) | G23: =IF(F23="","",E23*F23)
A24: Round of 64 | B24: R64_G21 | C24: (6) BYU vs (11) Texas | D24: BYU | E24: 1 | F24: =IF(Master_Results!$D$24="","",IF(D24=Master_Results!$D$24,1,0)) | G24: =IF(F24="","",E24*F24)
A25: Round of 64 | B25: R64_G22 | C25: (3) Gonzaga vs (14) Kennesaw St | D25: Gonzaga | E25: 1 | F25: =IF(Master_Results!$D$25="","",IF(D25=Master_Results!$D$25,1,0)) | G25: =IF(F25="","",E25*F25)
A26: Round of 64 | B26: R64_G23 | C26: (7) Miami (FL) vs (10) Missouri | D26: Miami | E26: 1 | F26: =IF(Master_Results!$D$26="","",IF(D26=Master_Results!$D$26,1,0)) | G26: =IF(F26="","",E26*F26)
A27: Round of 64 | B27: R64_G24 | C27: (2) Purdue vs (15) Queens | D27: Purdue | E27: 1 | F27: =IF(Master_Results!$D$27="","",IF(D27=Master_Results!$D$27,1,0)) | G27: =IF(F27="","",E27*F27)
A28: Round of 64 | B28: R64_G25 | C28: (1) Michigan vs (16) Howard | D28: Michigan | E28: 1 | F28: =IF(Master_Results!$D$28="","",IF(D28=Master_Results!$D$28,1,0)) | G28: =IF(F28="","",E28*F28)
A29: Round of 64 | B29: R64_G26 | C29: (8) Georgia vs (9) St. Louis | D29: Georgia | E29: 1 | F29: =IF(Master_Results!$D$29="","",IF(D29=Master_Results!$D$29,1,0)) | G29: =IF(F29="","",E29*F29)
A30: Round of 64 | B30: R64_G27 | C30: (5) Texas Tech vs (12) Akron | D30: Akron | E30: 1 | F30: =IF(Master_Results!$D$30="","",IF(D30=Master_Results!$D$30,1,0)) | G30: =IF(F30="","",E30*F30)
A31: Round of 64 | B31: R64_G28 | C31: (4) Alabama vs (13) Hofstra | D31: Alabama | E31: 1 | F31: =IF(Master_Results!$D$31="","",IF(D31=Master_Results!$D$31,1,0)) | G31: =IF(F31="","",E31*F31)
A32: Round of 64 | B32: R64_G29 | C32: (6) Tennessee vs (11) Miami (OH) | D32: Tennessee | E32: 1 | F32: =IF(Master_Results!$D$32="","",IF(D32=Master_Results!$D$32,1,0)) | G32: =IF(F32="","",E32*F32)
A33: Round of 64 | B33: R64_G30 | C33: (3) Virginia vs (14) Wright St | D33: Virginia | E33: 1 | F33: =IF(Master_Results!$D$33="","",IF(D33=Master_Results!$D$33,1,0)) | G33: =IF(F33="","",E33*F33)
A34: Round of 64 | B34: R64_G31 | C34: (7) Kentucky vs (10) Santa Clara | D34: Kentucky | E34: 1 | F34: =IF(Master_Results!$D$34="","",IF(D34=Master_Results!$D$34,1,0)) | G34: =IF(F34="","",E34*F34)
A35: Round of 64 | B35: R64_G32 | C35: (2) Iowa St vs (15) Tenn St | D35: Iowa State | E35: 1 | F35: =IF(Master_Results!$D$35="","",IF(D35=Master_Results!$D$35,1,0)) | G35: =IF(F35="","",E35*F35)
A36: ▸ ROUND OF 32 • 2 pts each
A37: Round of 32 | B37: Rou_G1 | C37: Winner Game 1 & 2 | D37: Duke | E37: 2 | F37: =IF(Master_Results!$D$37="","",IF(D37=Master_Results!$D$37,1,0)) | G37: =IF(F37="","",E37*F37)
A38: Round of 32 | B38: Rou_G2 | C38: Winner Game 3 & 4 | D38: Kansas | E38: 2 | F38: =IF(Master_Results!$D$38="","",IF(D38=Master_Results!$D$38,1,0)) | G38: =IF(F38="","",E38*F38)
A39: Round of 32 | B39: Rou_G3 | C39: Winner Game 5 & 6 | D39: Michigan St | E39: 2 | F39: =IF(Master_Results!$D$39="","",IF(D39=Master_Results!$D$39,1,0)) | G39: =IF(F39="","",E39*F39)
A40: Round of 32 | B40: Rou_G4 | C40: Winner Game 7 & 8 | D40: UConn | E40: 2 | F40: =IF(Master_Results!$D$40="","",IF(D40=Master_Results!$D$40,1,0)) | G40: =IF(F40="","",E40*F40)
...

Sheet Chuck
A1: 🏀 CHUCK'S 2026 MARCH MADNESS BRACKET
A2: Round | B2: Game ID | C2: Matchup | D2: Pick | E2: Pts Value | F2: Result | G2: Pts Earned
A3: ▸ ROUND OF 64 • 1 pt each
A4: Round of 64 | B4: R64_G1 | C4: (1) Duke vs (16) Siena | D4: Duke | E4: 1 | F4: =IF(Master_Results!$D$4="","",IF(D4=Master_Results!$D$4,1,0)) | G4: =IF(F4="","",E4*F4)
A5: Round of 64 | B5: R64_G2 | C5: (8) Ohio St vs (9) TCU | D5: Ohio State | E5: 1 | F5: =IF(Master_Results!$D$5="","",IF(D5=Master_Results!$D$5,1,0)) | G5: =IF(F5="","",E5*F5)
A6: Round of 64 | B6: R64_G3 | C6: (5) St. John's vs (12) Northern Iowa | D6: St. John | E6: 1 | F6: =IF(Master_Results!$D$6="","",IF(D6=Master_Results!$D$6,1,0)) | G6: =IF(F6="","",E6*F6)
A7: Round of 64 | B7: R64_G4 | C7: (4) Kansas vs (13) Cal Baptist | D7: Kansas | E7: 1 | F7: =IF(Master_Results!$D$7="","",IF(D7=Master_Results!$D$7,1,0)) | G7: =IF(F7="","",E7*F7)
A8: Round of 64 | B8: R64_G5 | C8: (6) Louisville vs (11) South Florida | D8: Louisville | E8: 1 | F8: =IF(Master_Results!$D$8="","",IF(D8=Master_Results!$D$8,1,0)) | G8: =IF(F8="","",E8*F8)
A9: Round of 64 | B9: R64_G6 | C9: (3) Michigan St vs (14) ND State | D9: Mich St | E9: 1 | F9: =IF(Master_Results!$D$9="","",IF(D9=Master_Results!$D$9,1,0)) | G9: =IF(F9="","",E9*F9)
A10: Round of 64 | B10: R64_G7 | C10: (7) UCLA vs (10) UCF | D10: UCF | E10: 1 | F10: =IF(Master_Results!$D$10="","",IF(D10=Master_Results!$D$10,1,0)) | G10: =IF(F10="","",E10*F10)
A11: Round of 64 | B11: R64_G8 | C11: (2) UConn vs (15) Furman | D11: UConn | E11: 1 | F11: =IF(Master_Results!$D$11="","",IF(D11=Master_Results!$D$11,1,0)) | G11: =IF(F11="","",E11*F11)
A12: Round of 64 | B12: R64_G9 | C12: (1) Florida vs (16) Prairie View A&M | D12: Florida | E12: 1 | F12: =IF(Master_Results!$D$12="","",IF(D12=Master_Results!$D$12,1,0)) | G12: =IF(F12="","",E12*F12)
A13: Round of 64 | B13: R64_G10 | C13: (8) Clemson vs (9) Iowa | D13: Iowa | E13: 1 | F13: =IF(Master_Results!$D$13="","",IF(D13=Master_Results!$D$13,1,0)) | G13: =IF(F13="","",E13*F13)
A14: Round of 64 | B14: R64_G11 | C14: (5) Vandy vs (12) McNeese | D14: Vandy | E14: 1 | F14: =IF(Master_Results!$D$14="","",IF(D14=Master_Results!$D$14,1,0)) | G14: =IF(F14="","",E14*F14)
A15: Round of 64 | B15: R64_G12 | C15: (4) Nebraska vs (13) Troy | D15: Nebraska | E15: 1 | F15: =IF(Master_Results!$D$15="","",IF(D15=Master_Results!$D$15,1,0)) | G15: =IF(F15="","",E15*F15)
A16: Round of 64 | B16: R64_G13 | C16: (6) North Carolina vs (11) VCU | D16: North Carolina | E16: 1 | F16: =IF(Master_Results!$D$16="","",IF(D16=Master_Results!$D$16,1,0)) | G16: =IF(F16="","",E16*F16)
A17: Round of 64 | B17: R64_G14 | C17: (3) Illinois vs (14) Penn | D17: Illinois | E17: 1 | F17: =IF(Master_Results!$D$17="","",IF(D17=Master_Results!$D$17,1,0)) | G17: =IF(F17="","",E17*F17)
A18: Round of 64 | B18: R64_G15 | C18: (7) St. Mary's vs (10) Texas A&M | D18: St. Mary's | E18: 1 | F18: =IF(Master_Results!$D$18="","",IF(D18=Master_Results!$D$18,1,0)) | G18: =IF(F18="","",E18*F18)
A19: Round of 64 | B19: R64_G16 | C19: (2) Houston vs (15) Idaho | D19: Houston | E19: 1 | F19: =IF(Master_Results!$D$19="","",IF(D19=Master_Results!$D$19,1,0)) | G19: =IF(F19="","",E19*F19)
A20: Round of 64 | B20: R64_G17 | C20: (1) Arizona vs (16) Long Island | D20: Arizona | E20: 1 | F20: =IF(Master_Results!$D$20="","",IF(D20=Master_Results!$D$20,1,0)) | G20: =IF(F20="","",E20*F20)
A21: Round of 64 | B21: R64_G18 | C21: (8) Villanova vs (9) Utah St | D21: Villanova | E21: 1 | F21: =IF(Master_Results!$D$21="","",IF(D21=Master_Results!$D$21,1,0)) | G21: =IF(F21="","",E21*F21)
A22: Round of 64 | B22: R64_G19 | C22: (5) Wisconsin vs (12) High Point | D22: Wisconsin | E22: 1 | F22: =IF(Master_Results!$D$22="","",IF(D22=Master_Results!$D$22,1,0)) | G22: =IF(F22="","",E22*F22)
A23: Round of 64 | B23: R64_G20 | C23: (4) Arkansas vs (13) Hawai'i | D23: Arkansas | E23: 1 | F23: =IF(Master_Results!$D$23="","",IF(D23=Master_Results!$D$23,1,0)) | G23: =IF(F23="","",E23*F23)
A24: Round of 64 | B24: R64_G21 | C24: (6) BYU vs (11) Texas | D24: BYU | E24: 1 | F24: =IF(Master_Results!$D$24="","",IF(D24=Master_Results!$D$24,1,0)) | G24: =IF(F24="","",E24*F24)
A25: Round of 64 | B25: R64_G22 | C25: (3) Gonzaga vs (14) Kennesaw St | D25: Gonzaga | E25: 1 | F25: =IF(Master_Results!$D$25="","",IF(D25=Master_Results!$D$25,1,0)) | G25: =IF(F25="","",E25*F25)
A26: Round of 64 | B26: R64_G23 | C26: (7) Miami (FL) vs (10) Missouri | D26: Miami | E26: 1 | F26: =IF(Master_Results!$D$26="","",IF(D26=Master_Results!$D$26,1,0)) | G26: =IF(F26="","",E26*F26)
A27: Round of 64 | B27: R64_G24 | C27: (2) Purdue vs (15) Queens | D27: Purdue | E27: 1 | F27: =IF(Master_Results!$D$27="","",IF(D27=Master_Results!$D$27,1,0)) | G27: =IF(F27="","",E27*F27)
A28: Round of 64 | B28: R64_G25 | C28: (1) Michigan vs (16) Howard | D28: Michigan | E28: 1 | F28: =IF(Master_Results!$D$28="","",IF(D28=Master_Results!$D$28,1,0)) | G28: =IF(F28="","",E28*F28)
A29: Round of 64 | B29: R64_G26 | C29: (8) Georgia vs (9) St. Louis | D29: St. Louis | E29: 1 | F29: =IF(Master_Results!$D$29="","",IF(D29=Master_Results!$D$29,1,0)) | G29: =IF(F29="","",E29*F29)
A30: Round of 64 | B30: R64_G27 | C30: (5) Texas Tech vs (12) Akron | D30: Texas Tech | E30: 1 | F30: =IF(Master_Results!$D$30="","",IF(D30=Master_Results!$D$30,1,0)) | G30: =IF(F30="","",E30*F30)
A31: Round of 64 | B31: R64_G28 | C31: (4) Alabama vs (13) Hofstra | D31: Alabama | E31: 1 | F31: =IF(Master_Results!$D$31="","",IF(D31=Master_Results!$D$31,1,0)) | G31: =IF(F31="","",E31*F31)
A32: Round of 64 | B32: R64_G29 | C32: (6) Tennessee vs (11) Miami (OH) | D32: Tennessee | E32: 1 | F32: =IF(Master_Results!$D$32="","",IF(D32=Master_Results!$D$32,1,0)) | G32: =IF(F32="","",E32*F32)
A33: Round of 64 | B33: R64_G30 | C33: (3) Virginia vs (14) Wright St | D33: Virginia | E33: 1 | F33: =IF(Master_Results!$D$33="","",IF(D33=Master_Results!$D$33,1,0)) | G33: =IF(F33="","",E33*F33)
A34: Round of 64 | B34: R64_G31 | C34: (7) Kentucky vs (10) Santa Clara | D34: Kentucky | E34: 1 | F34: =IF(Master_Results!$D$34="","",IF(D34=Master_Results!$D$34,1,0)) | G34: =IF(F34="","",E34*F34)
A35: Round of 64 | B35: R64_G32 | C35: (2) Iowa St vs (15) Tenn St | D35: Iowa State | E35: 1 | F35: =IF(Master_Results!$D$35="","",IF(D35=Master_Results!$D$35,1,0)) | G35: =IF(F35="","",E35*F35)
A36: ▸ ROUND OF 32 • 2 pts each
A37: Round of 32 | B37: Rou_G1 | C37: Winner Game 1 & 2 | D37: Duke | E37: 2 | F37: =IF(Master_Results!$D$37="","",IF(D37=Master_Results!$D$37,1,0)) | G37: =IF(F37="","",E37*F37)
A38: Round of 32 | B38: Rou_G2 | C38: Winner Game 3 & 4 | D38: Kansas | E38: 2 | F38: =IF(Master_Results!$D$38="","",IF(D38=Master_Results!$D$38,1,0)) | G38: =IF(F38="","",E38*F38)
A39: Round of 32 | B39: Rou_G3 | C39: Winner Game 5 & 6 | D39: Mich St | E39: 2 | F39: =IF(Master_Results!$D$39="","",IF(D39=Master_Results!$D$39,1,0)) | G39: =IF(F39="","",E39*F39)
A40: Round of 32 | B40: Rou_G4 | C40: Winner Game 7 & 8 | D40: UConn | E40: 2 | F40: =IF(Master_Results!$D$40="","",IF(D40=Master_Results!$D$40,1,0)) | G40: =IF(F40="","",E40*F40)
...

Sheet Porter
A1: 🏀 PORTER'S 2026 MARCH MADNESS BRACKET
A2: Round | B2: Game ID | C2: Matchup | D2: Pick | E2: Pts Value | F2: Result | G2: Pts Earned
A3: ▸ ROUND OF 64 • 1 pt each
A4: Round of 64 | B4: R64_G1 | C4: (1) Duke vs (16) Siena | D4: Duke | E4: 1 | F4: =IF(Master_Results!$D$4="","",IF(D4=Master_Results!$D$4,1,0)) | G4: =IF(F4="","",E4*F4)
A5: Round of 64 | B5: R64_G2 | C5: (8) Ohio St vs (9) TCU | D5: Ohio State | E5: 1 | F5: =IF(Master_Results!$D$5="","",IF(D5=Master_Results!$D$5,1,0)) | G5: =IF(F5="","",E5*F5)
A6: Round of 64 | B6: R64_G3 | C6: (5) St. John's vs (12) Northern Iowa | D6: Northern Iowa | E6: 1 | F6: =IF(Master_Results!$D$6="","",IF(D6=Master_Results!$D$6,1,0)) | G6: =IF(F6="","",E6*F6)
A7: Round of 64 | B7: R64_G4 | C7: (4) Kansas vs (13) Cal Baptist | D7: Kansas | E7: 1 | F7: =IF(Master_Results!$D$7="","",IF(D7=Master_Results!$D$7,1,0)) | G7: =IF(F7="","",E7*F7)
A8: Round of 64 | B8: R64_G5 | C8: (6) Louisville vs (11) South Florida | D8: South Florida | E8: 1 | F8: =IF(Master_Results!$D$8="","",IF(D8=Master_Results!$D$8,1,0)) | G8: =IF(F8="","",E8*F8)
A9: Round of 64 | B9: R64_G6 | C9: (3) Michigan St vs (14) ND State | D9: Mich St | E9: 1 | F9: =IF(Master_Results!$D$9="","",IF(D9=Master_Results!$D$9,1,0)) | G9: =IF(F9="","",E9*F9)
A10: Round of 64 | B10: R64_G7 | C10: (7) UCLA vs (10) UCF | D10: UCLA | E10: 1 | F10: =IF(Master_Results!$D$10="","",IF(D10=Master_Results!$D$10,1,0)) | G10: =IF(F10="","",E10*F10)
A11: Round of 64 | B11: R64_G8 | C11: (2) UConn vs (15) Furman | D11: UConn | E11: 1 | F11: =IF(Master_Results!$D$11="","",IF(D11=Master_Results!$D$11,1,0)) | G11: =IF(F11="","",E11*F11)
A12: Round of 64 | B12: R64_G9 | C12: (1) Florida vs (16) Prairie View A&M | D12: Florida | E12: 1 | F12: =IF(Master_Results!$D$12="","",IF(D12=Master_Results!$D$12,1,0)) | G12: =IF(F12="","",E12*F12)
A13: Round of 64 | B13: R64_G10 | C13: (8) Clemson vs (9) Iowa | D13: Clemson | E13: 1 | F13: =IF(Master_Results!$D$13="","",IF(D13=Master_Results!$D$13,1,0)) | G13: =IF(F13="","",E13*F13)
A14: Round of 64 | B14: R64_G11 | C14: (5) Vandy vs (12) McNeese | D14: Vandy | E14: 1 | F14: =IF(Master_Results!$D$14="","",IF(D14=Master_Results!$D$14,1,0)) | G14: =IF(F14="","",E14*F14)
A15: Round of 64 | B15: R64_G12 | C15: (4) Nebraska vs (13) Troy | D15: Nebraska | E15: 1 | F15: =IF(Master_Results!$D$15="","",IF(D15=Master_Results!$D$15,1,0)) | G15: =IF(F15="","",E15*F15)
A16: Round of 64 | B16: R64_G13 | C16: (6) North Carolina vs (11) VCU | D16: North Carolina | E16: 1 | F16: =IF(Master_Results!$D$16="","",IF(D16=Master_Results!$D$16,1,0)) | G16: =IF(F16="","",E16*F16)
A17: Round of 64 | B17: R64_G14 | C17: (3) Illinois vs (14) Penn | D17: Illinois | E17: 1 | F17: =IF(Master_Results!$D$17="","",IF(D17=Master_Results!$D$17,1,0)) | G17: =IF(F17="","",E17*F17)
A18: Round of 64 | B18: R64_G15 | C18: (7) St. Mary's vs (10) Texas A&M | D18: St. Mary's | E18: 1 | F18: =IF(Master_Results!$D$18="","",IF(D18=Master_Results!$D$18,1,0)) | G18: =IF(F18="","",E18*F18)
A19: Round of 64 | B19: R64_G16 | C19: (2) Houston vs (15) Idaho | D19: Houston | E19: 1 | F19: =IF(Master_Results!$D$19="","",IF(D19=Master_Results!$D$19,1,0)) | G19: =IF(F19="","",E19*F19)
A20: Round of 64 | B20: R64_G17 | C20: (1) Arizona vs (16) Long Island | D20: Arizona | E20: 1 | F20: =IF(Master_Results!$D$20="","",IF(D20=Master_Results!$D$20,1,0)) | G20: =IF(F20="","",E20*F20)
A21: Round of 64 | B21: R64_G18 | C21: (8) Villanova vs (9) Utah St | D21: Villanova | E21: 1 | F21: =IF(Master_Results!$D$21="","",IF(D21=Master_Results!$D$21,1,0)) | G21: =IF(F21="","",E21*F21)
A22: Round of 64 | B22: R64_G19 | C22: (5) Wisconsin vs (12) High Point | D22: High Point | E22: 1 | F22: =IF(Master_Results!$D$22="","",IF(D22=Master_Results!$D$22,1,0)) | G22: =IF(F22="","",E22*F22)
A23: Round of 64 | B23: R64_G20 | C23: (4) Arkansas vs (13) Hawai'i | D23: Arkansas | E23: 1 | F23: =IF(Master_Results!$D$23="","",IF(D23=Master_Results!$D$23,1,0)) | G23: =IF(F23="","",E23*F23)
A24: Round of 64 | B24: R64_G21 | C24: (6) BYU vs (11) Texas | D24: BYU | E24: 1 | F24: =IF(Master_Results!$D$24="","",IF(D24=Master_Results!$D$24,1,0)) | G24: =IF(F24="","",E24*F24)
A25: Round of 64 | B25: R64_G22 | C25: (3) Gonzaga vs (14) Kennesaw St | D25: Gonzaga | E25: 1 | F25: =IF(Master_Results!$D$25="","",IF(D25=Master_Results!$D$25,1,0)) | G25: =IF(F25="","",E25*F25)
A26: Round of 64 | B26: R64_G23 | C26: (7) Miami (FL) vs (10) Missouri | D26: Miami | E26: 1 | F26: =IF(Master_Results!$D$26="","",IF(D26=Master_Results!$D$26,1,0)) | G26: =IF(F26="","",E26*F26)
A27: Round of 64 | B27: R64_G24 | C27: (2) Purdue vs (15) Queens | D27: Purdue | E27: 1 | F27: =IF(Master_Results!$D$27="","",IF(D27=Master_Results!$D$27,1,0)) | G27: =IF(F27="","",E27*F27)
A28: Round of 64 | B28: R64_G25 | C28: (1) Michigan vs (16) Howard | D28: Michigan | E28: 1 | F28: =IF(Master_Results!$D$28="","",IF(D28=Master_Results!$D$28,1,0)) | G28: =IF(F28="","",E28*F28)
A29: Round of 64 | B29: R64_G26 | C29: (8) Georgia vs (9) St. Louis | D29: Georgia | E29: 1 | F29: =IF(Master_Results!$D$29="","",IF(D29=Master_Results!$D$29,1,0)) | G29: =IF(F29="","",E29*F29)
A30: Round of 64 | B30: R64_G27 | C30: (5) Texas Tech vs (12) Akron | D30: Texas Tech | E30: 1 | F30: =IF(Master_Results!$D$30="","",IF(D30=Master_Results!$D$30,1,0)) | G30: =IF(F30="","",E30*F30)
A31: Round of 64 | B31: R64_G28 | C31: (4) Alabama vs (13) Hofstra | D31: Alabama | E31: 1 | F31: =IF(Master_Results!$D$31="","",IF(D31=Master_Results!$D$31,1,0)) | G31: =IF(F31="","",E31*F31)
A32: Round of 64 | B32: R64_G29 | C32: (6) Tennessee vs (11) Miami (OH) | D32: Tennessee | E32: 1 | F32: =IF(Master_Results!$D$32="","",IF(D32=Master_Results!$D$32,1,0)) | G32: =IF(F32="","",E32*F32)
A33: Round of 64 | B33: R64_G30 | C33: (3) Virginia vs (14) Wright St | D33: Virginia | E33: 1 | F33: =IF(Master_Results!$D$33="","",IF(D33=Master_Results!$D$33,1,0)) | G33: =IF(F33="","",E33*F33)
A34: Round of 64 | B34: R64_G31 | C34: (7) Kentucky vs (10) Santa Clara | D34: Santa Clara | E34: 1 | F34: =IF(Master_Results!$D$34="","",IF(D34=Master_Results!$D$34,1,0)) | G34: =IF(F34="","",E34*F34)
A35: Round of 64 | B35: R64_G32 | C35: (2) Iowa St vs (15) Tenn St | D35: Iowa State | E35: 1 | F35: =IF(Master_Results!$D$35="","",IF(D35=Master_Results!$D$35,1,0)) | G35: =IF(F35="","",E35*F35)
A36: ▸ ROUND OF 32 • 2 pts each
A37: Round of 32 | B37: Rou_G1 | C37: Winner Game 1 & 2 | D37: Duke | E37: 2 | F37: =IF(Master_Results!$D$37="","",IF(D37=Master_Results!$D$37,1,0)) | G37: =IF(F37="","",E37*F37)
A38: Round of 32 | B38: Rou_G2 | C38: Winner Game 3 & 4 | D38: Kansas | E38: 2 | F38: =IF(Master_Results!$D$38="","",IF(D38=Master_Results!$D$38,1,0)) | G38: =IF(F38="","",E38*F38)
A39: Round of 32 | B39: Rou_G3 | C39: Winner Game 5 & 6 | D39: Mich St | E39: 2 | F39: =IF(Master_Results!$D$39="","",IF(D39=Master_Results!$D$39,1,0)) | G39: =IF(F39="","",E39*F39)
A40: Round of 32 | B40: Rou_G4 | C40: Winner Game 7 & 8 | D40: UConn | E40: 2 | F40: =IF(Master_Results!$D$40="","",IF(D40=Master_Results!$D$40,1,0)) | G40: =IF(F40="","",E40*F40)
...

Sheet Raman
A1: 🏀 RAMAN'S 2026 MARCH MADNESS BRACKET
A2: Round | B2: Game ID | C2: Matchup | D2: Pick | E2: Pts Value | F2: Result | G2: Pts Earned
A3: ▸ ROUND OF 64 • 1 pt each
A4: Round of 64 | B4: R64_G1 | C4: (1) Duke vs (16) Siena | D4: Duke | E4: 1 | F4: =IF(Master_Results!$D$4="","",IF(D4=Master_Results!$D$4,1,0)) | G4: =IF(F4="","",E4*F4)
A5: Round of 64 | B5: R64_G2 | C5: (8) Ohio St vs (9) TCU | D5: TCU | E5: 1 | F5: =IF(Master_Results!$D$5="","",IF(D5=Master_Results!$D$5,1,0)) | G5: =IF(F5="","",E5*F5)
A6: Round of 64 | B6: R64_G3 | C6: (5) St. John's vs (12) Northern Iowa | D6: St. John | E6: 1 | F6: =IF(Master_Results!$D$6="","",IF(D6=Master_Results!$D$6,1,0)) | G6: =IF(F6="","",E6*F6)
A7: Round of 64 | B7: R64_G4 | C7: (4) Kansas vs (13) Cal Baptist | D7: Kansas | E7: 1 | F7: =IF(Master_Results!$D$7="","",IF(D7=Master_Results!$D$7,1,0)) | G7: =IF(F7="","",E7*F7)
A8: Round of 64 | B8: R64_G5 | C8: (6) Louisville vs (11) South Florida | D8: Louisville | E8: 1 | F8: =IF(Master_Results!$D$8="","",IF(D8=Master_Results!$D$8,1,0)) | G8: =IF(F8="","",E8*F8)
A9: Round of 64 | B9: R64_G6 | C9: (3) Michigan St vs (14) ND State | D9: Mich St | E9: 1 | F9: =IF(Master_Results!$D$9="","",IF(D9=Master_Results!$D$9,1,0)) | G9: =IF(F9="","",E9*F9)
A10: Round of 64 | B10: R64_G7 | C10: (7) UCLA vs (10) UCF | D10: UCLA | E10: 1 | F10: =IF(Master_Results!$D$10="","",IF(D10=Master_Results!$D$10,1,0)) | G10: =IF(F10="","",E10*F10)
A11: Round of 64 | B11: R64_G8 | C11: (2) UConn vs (15) Furman | D11: UConn | E11: 1 | F11: =IF(Master_Results!$D$11="","",IF(D11=Master_Results!$D$11,1,0)) | G11: =IF(F11="","",E11*F11)
A12: Round of 64 | B12: R64_G9 | C12: (1) Florida vs (16) Prairie View A&M | D12: Florida | E12: 1 | F12: =IF(Master_Results!$D$12="","",IF(D12=Master_Results!$D$12,1,0)) | G12: =IF(F12="","",E12*F12)
A13: Round of 64 | B13: R64_G10 | C13: (8) Clemson vs (9) Iowa | D13: Clemson | E13: 1 | F13: =IF(Master_Results!$D$13="","",IF(D13=Master_Results!$D$13,1,0)) | G13: =IF(F13="","",E13*F13)
A14: Round of 64 | B14: R64_G11 | C14: (5) Vandy vs (12) McNeese | D14: Vandy | E14: 1 | F14: =IF(Master_Results!$D$14="","",IF(D14=Master_Results!$D$14,1,0)) | G14: =IF(F14="","",E14*F14)
A15: Round of 64 | B15: R64_G12 | C15: (4) Nebraska vs (13) Troy | D15: Nebraska | E15: 1 | F15: =IF(Master_Results!$D$15="","",IF(D15=Master_Results!$D$15,1,0)) | G15: =IF(F15="","",E15*F15)
A16: Round of 64 | B16: R64_G13 | C16: (6) North Carolina vs (11) VCU | D16: North Carolina | E16: 1 | F16: =IF(Master_Results!$D$16="","",IF(D16=Master_Results!$D$16,1,0)) | G16: =IF(F16="","",E16*F16)
A17: Round of 64 | B17: R64_G14 | C17: (3) Illinois vs (14) Penn | D17: Illinois | E17: 1 | F17: =IF(Master_Results!$D$17="","",IF(D17=Master_Results!$D$17,1,0)) | G17: =IF(F17="","",E17*F17)
A18: Round of 64 | B18: R64_G15 | C18: (7) St. Mary's vs (10) Texas A&M | D18: Texas A&M | E18: 1 | F18: =IF(Master_Results!$D$18="","",IF(D18=Master_Results!$D$18,1,0)) | G18: =IF(F18="","",E18*F18)
A19: Round of 64 | B19: R64_G16 | C19: (2) Houston vs (15) Idaho | D19: Houston | E19: 1 | F19: =IF(Master_Results!$D$19="","",IF(D19=Master_Results!$D$19,1,0)) | G19: =IF(F19="","",E19*F19)
A20: Round of 64 | B20: R64_G17 | C20: (1) Arizona vs (16) Long Island | D20: Arizona | E20: 1 | F20: =IF(Master_Results!$D$20="","",IF(D20=Master_Results!$D$20,1,0)) | G20: =IF(F20="","",E20*F20)
A21: Round of 64 | B21: R64_G18 | C21: (8) Villanova vs (9) Utah St | D21: Villanova | E21: 1 | F21: =IF(Master_Results!$D$21="","",IF(D21=Master_Results!$D$21,1,0)) | G21: =IF(F21="","",E21*F21)
A22: Round of 64 | B22: R64_G19 | C22: (5) Wisconsin vs (12) High Point | D22: Wisconsin | E22: 1 | F22: =IF(Master_Results!$D$22="","",IF(D22=Master_Results!$D$22,1,0)) | G22: =IF(F22="","",E22*F22)
A23: Round of 64 | B23: R64_G20 | C23: (4) Arkansas vs (13) Hawai'i | D23: Arkansas | E23: 1 | F23: =IF(Master_Results!$D$23="","",IF(D23=Master_Results!$D$23,1,0)) | G23: =IF(F23="","",E23*F23)
A24: Round of 64 | B24: R64_G21 | C24: (6) BYU vs (11) Texas | D24: BYU | E24: 1 | F24: =IF(Master_Results!$D$24="","",IF(D24=Master_Results!$D$24,1,0)) | G24: =IF(F24="","",E24*F24)
A25: Round of 64 | B25: R64_G22 | C25: (3) Gonzaga vs (14) Kennesaw St | D25: Gonzaga | E25: 1 | F25: =IF(Master_Results!$D$25="","",IF(D25=Master_Results!$D$25,1,0)) | G25: =IF(F25="","",E25*F25)
A26: Round of 64 | B26: R64_G23 | C26: (7) Miami (FL) vs (10) Missouri | D26: Miami | E26: 1 | F26: =IF(Master_Results!$D$26="","",IF(D26=Master_Results!$D$26,1,0)) | G26: =IF(F26="","",E26*F26)
A27: Round of 64 | B27: R64_G24 | C27: (2) Purdue vs (15) Queens | D27: Purdue | E27: 1 | F27: =IF(Master_Results!$D$27="","",IF(D27=Master_Results!$D$27,1,0)) | G27: =IF(F27="","",E27*F27)
A28: Round of 64 | B28: R64_G25 | C28: (1) Michigan vs (16) Howard | D28: Michigan | E28: 1 | F28: =IF(Master_Results!$D$28="","",IF(D28=Master_Results!$D$28,1,0)) | G28: =IF(F28="","",E28*F28)
A29: Round of 64 | B29: R64_G26 | C29: (8) Georgia vs (9) St. Louis | D29: St. Louis | E29: 1 | F29: =IF(Master_Results!$D$29="","",IF(D29=Master_Results!$D$29,1,0)) | G29: =IF(F29="","",E29*F29)
A30: Round of 64 | B30: R64_G27 | C30: (5) Texas Tech vs (12) Akron | D30: Texas Tech | E30: 1 | F30: =IF(Master_Results!$D$30="","",IF(D30=Master_Results!$D$30,1,0)) | G30: =IF(F30="","",E30*F30)
A31: Round of 64 | B31: R64_G28 | C31: (4) Alabama vs (13) Hofstra | D31: Alabama | E31: 1 | F31: =IF(Master_Results!$D$31="","",IF(D31=Master_Results!$D$31,1,0)) | G31: =IF(F31="","",E31*F31)
A32: Round of 64 | B32: R64_G29 | C32: (6) Tennessee vs (11) Miami (OH) | D32: Tennessee | E32: 1 | F32: =IF(Master_Results!$D$32="","",IF(D32=Master_Results!$D$32,1,0)) | G32: =IF(F32="","",E32*F32)
A33: Round of 64 | B33: R64_G30 | C33: (3) Virginia vs (14) Wright St | D33: Virginia | E33: 1 | F33: =IF(Master_Results!$D$33="","",IF(D33=Master_Results!$D$33,1,0)) | G33: =IF(F33="","",E33*F33)
A34: Round of 64 | B34: R64_G31 | C34: (7) Kentucky vs (10) Santa Clara | D34: Kentucky | E34: 1 | F34: =IF(Master_Results!$D$34="","",IF(D34=Master_Results!$D$34,1,0)) | G34: =IF(F34="","",E34*F34)
A35: Round of 64 | B35: R64_G32 | C35: (2) Iowa St vs (15) Tenn St | D35: Iowa State | E35: 1 | F35: =IF(Master_Results!$D$35="","",IF(D35=Master_Results!$D$35,1,0)) | G35: =IF(F35="","",E35*F35)
A36: ▸ ROUND OF 32 • 2 pts each
A37: Round of 32 | B37: Rou_G1 | C37: Winner Game 1 & 2 | D37: Duke | E37: 2 | F37: =IF(Master_Results!$D$37="","",IF(D37=Master_Results!$D$37,1,0)) | G37: =IF(F37="","",E37*F37)
A38: Round of 32 | B38: Rou_G2 | C38: Winner Game 3 & 4 | D38: St. John | E38: 2 | F38: =IF(Master_Results!$D$38="","",IF(D38=Master_Results!$D$38,1,0)) | G38: =IF(F38="","",E38*F38)
A39: Round of 32 | B39: Rou_G3 | C39: Winner Game 5 & 6 | D39: Mich St | E39: 2 | F39: =IF(Master_Results!$D$39="","",IF(D39=Master_Results!$D$39,1,0)) | G39: =IF(F39="","",E39*F39)
A40: Round of 32 | B40: Rou_G4 | C40: Winner Game 7 & 8 | D40: UCLA | E40: 2 | F40: =IF(Master_Results!$D$40="","",IF(D40=Master_Results!$D$40,1,0)) | G40: =IF(F40="","",E40*F40)
...

Sheet Master_Results
A1: 🏀 2026 NCAA TOURNAMENT — OFFICIAL RESULTS
A2: Round | B2: Game ID | C2: Matchup | D2: Actual Winner
A3: ▸ ROUND OF 64
A4: Round of 64 | B4: R64_G1 | C4: (1) Duke vs (16) Siena | D4: Duke
A5: Round of 64 | B5: R64_G2 | C5: (8) Ohio St vs (9) TCU | D5: TCU
A6: Round of 64 | B6: R64_G3 | C6: (5) St. John's vs (12) Northern Iowa
A7: Round of 64 | B7: R64_G4 | C7: (4) Kansas vs (13) Cal Baptist
A8: Round of 64 | B8: R64_G5 | C8: (6) Louisville vs (11) South Florida | D8: Louisville
A9: Round of 64 | B9: R64_G6 | C9: (3) Michigan St vs (14) ND State
A10: Round of 64 | B10: R64_G7 | C10: (7) UCLA vs (10) UCF
A11: Round of 64 | B11: R64_G8 | C11: (2) UConn vs (15) Furman
A12: Round of 64 | B12: R64_G9 | C12: (1) Florida vs (16) Prairie View A&M
A13: Round of 64 | B13: R64_G10 | C13: (8) Clemson vs (9) Iowa
A14: Round of 64 | B14: R64_G11 | C14: (5) Vandy vs (12) McNeese | D14: Vandy
A15: Round of 64 | B15: R64_G12 | C15: (4) Nebraska vs (13) Troy | D15: Nebraska
A16: Round of 64 | B16: R64_G13 | C16: (6) North Carolina vs (11) VCU | D16: VCU
A17: Round of 64 | B17: R64_G14 | C17: (3) Illinois vs (14) Penn
A18: Round of 64 | B18: R64_G15 | C18: (7) St. Mary's vs (10) Texas A&M
A19: Round of 64 | B19: R64_G16 | C19: (2) Houston vs (15) Idaho
A20: Round of 64 | B20: R64_G17 | C20: (1) Arizona vs (16) Long Island
A21: Round of 64 | B21: R64_G18 | C21: (8) Villanova vs (9) Utah St
A22: Round of 64 | B22: R64_G19 | C22: (5) Wisconsin vs (12) High Point | D22: High Point
A23: Round of 64 | B23: R64_G20 | C23: (4) Arkansas vs (13) Hawai'i | D23: Arkansas
A24: Round of 64 | B24: R64_G21 | C24: (6) BYU vs (11) Texas
A25: Round of 64 | B25: R64_G22 | C25: (3) Gonzaga vs (14) Kennesaw St
A26: Round of 64 | B26: R64_G23 | C26: (7) Miami (FL) vs (10) Missouri
A27: Round of 64 | B27: R64_G24 | C27: (2) Purdue vs (15) Queens
A28: Round of 64 | B28: R64_G25 | C28: (1) Michigan vs (16) Howard
A29: Round of 64 | B29: R64_G26 | C29: (8) Georgia vs (9) St. Louis
A30: Round of 64 | B30: R64_G27 | C30: (5) Texas Tech vs (12) Akron
A31: Round of 64 | B31: R64_G28 | C31: (4) Alabama vs (13) Hofstra
A32: Round of 64 | B32: R64_G29 | C32: (6) Tennessee vs (11) Miami (OH)
A33: Round of 64 | B33: R64_G30 | C33: (3) Virginia vs (14) Wright St
A34: Round of 64 | B34: R64_G31 | C34: (7) Kentucky vs (10) Santa Clara
A35: Round of 64 | B35: R64_G32 | C35: (2) Iowa St vs (15) Tenn St
A36: ▸ ROUND OF 32
A37: Round of 32 | B37: Rou_G1 | C37: Winner Game 1 & 2
A38: Round of 32 | B38: Rou_G2 | C38: Winner Game 3 & 4
A39: Round of 32 | B39: Rou_G3 | C39: Winner Game 5 & 6
A40: Round of 32 | B40: Rou_G4 | C40: Winner Game 7 & 8
...

Sheet 🏆 Leaderboard
A1: 🏆 2026 OFFICE MARCH MADNESS — LEADERBOARD
A2: Scores update automatically as results are entered in Master_Results
A3: Rank | B3: Participant | C3: Champion Pick | D3: Current Score | E3: Pts Remaining | F3: Max Possible
A4: =RANK(D4,$D$4:$D$9,0) | B4: Raman | C4: =Raman!D71 | D4: =Raman!G73 | E4: =Raman!H73 | F4: =D4+E4
A5: =RANK(D5,$D$4:$D$9,0) | B5: Porter | C5: =Porter!D71 | D5: =Porter!G73 | E5: =Porter!H73 | F5: =D5+E5
A6: =RANK(D6,$D$4:$D$9,0) | B6: Chuck | C6: =Chuck!D71 | D6: =Chuck!G73 | E6: =Chuck!H73 | F6: =D6+E6
A7: =RANK(D7,$D$4:$D$9,0) | B7: Shelly | C7: =Shelly!D71 | D7: =Shelly!G73 | E7: =Shelly!H73 | F7: =D7+E7
A8: =RANK(D8,$D$4:$D$9,0) | B8: Kim | C8: =Kim!D71 | D8: =Kim!G73 | E8: =Kim!H73 | F8: =D8+E8
A9: =RANK(D9,$D$4:$D$9,0) | B9: Tucker | C9: =Tucker!D71 | D9: =Tucker!G73 | E9: =Tucker!H73 | F9: =D9+E9
A11: SCORING GUIDE
A12: Round of 64 | B12: Round of 32 | C12: Sweet 16 | D12: Elite 8 | E12: Final Four | F12: Championship
A13: 1 pt | B13: 2 pts | C13: 4 pts | D13: 8 pts | E13: 16 pts | F13: 32 pts
